Workbook
Name AC: AC!$B$2:$C$15
Name AC_LM: AC_LM!$B$2:$C$3
Name AC_LMD: AC_LM!$H$3:$T$3
Name AC_LMI: AC_LM!$H$2:$T$2
Name ACD_1: AC!$H$35:$DQ$42
Name ACD_2: AC!$H$43:$DQ$43
Name ACD_3: AC!$H$44:$DQ$45
Name ACF: AC!$H$24:$DQ$34
Name ACI: AC!$H$2:$DQ$2
Name ACT: AC!$G$24
Name CTAX_D: EMI!$K$3:$K$3
Name FC: FC!$B$2:$C$6
Name FC_LD: FC_LD!$B$2:$C$3
Name FC_LDD: FC_LD!$H$7:$LYE$8
Name FC_LDI: FC_LD!$H$4:$LYE$6
Name FCD: FC!$H$12:$H$13
Name FCD_2: FC!$L$12:$L$13
Name FCF: FC!$H$4:$H$4
Name FCI: FC!$H$3:$H$3
Name FCS: FC!$H$8:$H$10
Name ID: IND!$B$1:$B$17
Name ID_AC: IND!$AA$2:$AA$115
Name ID_ACM: IND!$AC$2:$AC$115
Name ID_DCR: IND!$BI$2:$BI$2
Name ID_DM: IND!$BN$2:$BN$366
Name ID_DY: IND!$BL$2:$BL$366
Name ID_FC: IND!$AV$2:$AV$2
Name ID_IK: IND!$AL$2:$AL$6
Name ID_IKL: IND!$AQ$2:$AQ$5
Name ID_IT: IND!$T$2:$T$50
Name ID_ITM: IND!$W$2:$W$50
Name ID_ND: IND!$G$2:$G$3
Name ID_NDPD: IND!$K$2:$K$3
Name ID_NDTM: IND!$J$2:$J$3
Name ID_NDTY: IND!$I$2:$I$3
Name ID_NK: IND!$AG$2:$AG$51
Name ID_OTF: IND!$B$18:$B$19
Name ID_RG: IND!$O$2:$O$2
Name ID_RS: IND!$BA$2:$BA$6
Name ID_SIG: IND!$V$2:$V$50
Name ID_TM: IND!$BW$2:$BW$25
Name ID_TZD: IND!$CB$2:$CB$3
Name ID_WR: IND!$BR$2:$BR$2
Name ID_WRP: IND!$BT$2
Name ID_YR: IND!$BE$2:$BE$2
Name ID_YRD: IND!$BG$2:$BG$2
Name ID_YRD2: IND!$BH$2:$BH$2
Name IK: IK!$B$2:$C$7
Name IK_DK: IK_DK!$B$2:$C$8
Name IK_DKI: IK_DK!$H$4:$H$5
Name IK_DSD: IK_DK!$H$6:$H$7
Name IK_DSI: IK_DK!$G$6:$G$7
Name IK_EKD: IK_DK!$H$8:$H$10
Name IK_EKI: IK_DK!$G$8:$G$10
Name IK_MKD: IK_DK!$H$11:$H$13
Name IK_MKI: IK_DK!$G$11:$G$13
Name IKC: IK!$G$11:$K$11
Name IKD_1: IK!$G$12:$K$16
Name IKD_2: IK!$G$17:$K$21
Name IKF: IK!$G$6:$K$8

Sheet CASE
G3: AC_LM sheet | H3: LH2 | I3: MTS | J3: MTS2 | K3: AMS | L3: MCS | M3: NG_IS | N3: H2_IS | O3: LA_IS | P3: MC_IS | Q3: NGF | R3: H2F | S3: AMF | U3: NK_TP sheet
B4: Case | C4: 1 | H4: {=INDEX(H5:H10,$C$4)} -> 0 | I4: {=INDEX(I5:I10,$C$4)} -> -1 | J4: {=INDEX(J5:J10,$C$4)} -> 0 | K4: {=INDEX(K5:K10,$C$4)} -> 0 | L4: {=INDEX(L5:L10,$C$4)} -> 0 | M4: {=INDEX(M5:M10,$C$4)} -> -1 | N4: {=INDEX(N5:N10,$C$4)} -> 0 | O4: {=INDEX(O5:O10,$C$4)} -> 0 | ... S4: {=INDEX(S5:S10,$C$4)} -> 0 | U4: {=INDEX(U5:U10,$C$4)} -> 1
C5: 1: Synthetic methane (conv.) | G5: 1 | H5: 0 | I5: -1 | J5: 0 | K5: 0 | L5: 0 | M5: -1 | N5: 0 | O5: 0 | P5: 0 | Q5: -1 | R5: 0 | S5: 0 | U5: 1
C6: 2: LH2 | G6: 2 | H6: -1 | I6: 0 | J6: 0 | K6: 0 | L6: 0 | M6: 0 | N6: -1 | O6: 0 | P6: 0 | Q6: 0 | R6: -1 | S6: 0 | U6: 2
C7: 3: MCH | G7: 3 | H7: 0 | I7: 0 | J7: 0 | K7: -1 | L7: -1 | M7: 0 | N7: 0 | O7: 0 | P7: -1 | Q7: 0 | R7: -1 | S7: 0 | U7: 3
C8: 4: NH3 (cracking) | G8: 4 | H8: 0 | I8: 0 | J8: 0 | K8: -1 | L8: 0 | M8: 0 | N8: 0 | O8: -1 | P8: 0 | Q8: 0 | R8: -1 | S8: 0 | U8: 3
C9: 5: NH3 (direct consumption) | G9: 5 | H9: 0 | I9: 0 | J9: 0 | K9: -1 | L9: 0 | M9: 0 | N9: 0 | O9: -1 | P9: 0 | Q9: 0 | R9: 0 | S9: -1 | U9: 3
C10: 6: Synthetic methane (innov.) | G10: 6 | H10: 0 | I10: 0 | J10: -1 | K10: 0 | L10: 0 | M10: -1 | N10: 0 | O10: 0 | P10: 0 | Q10: -1 | R10: 0 | S10: 0 | U10: 1
B13: Emissions | C13: 0 | E13: Natural gas | F13: =IND!B25*FC!H13 -> 0.48045 | G13: tc/toe
C14: tC/toe
C15: ="-1: without constraint" -> -1: without constraint
B18: Grid electricity | C18: 0
C19: 0: without
C20: ="-1: with (importing country)" -> -1: with (importing country)

Sheet IND
A1: Node [ND] | B1: =ROWS(ID_ND) -> 2 | F1: =A1 -> Node [ND] | G1: Abb. | H1: ID | I1: Type | J1: Time zone | K1: Distance to port [km] | N1: =A2 -> Region [RG] | O1: Abb. | P1: ID | S1: =A3 -> Item [IT] | T1: Abb. | U1: ID | V1: Sign | W1: Mode | Z1: =A4 -> Activity [AC] | AA1: Abb. | AB1: ID | AC1: Mode | AF1: =A5 -> Nodal facility [NK] | AG1: Abb. | AH1: ID | AK1: =A6 -> Maritime trade facility [IK] | AL1: Abb. | AM1: ID | AP1: =A7 -> Land trade facility [IKL] | AQ1: Abb. | AR1: ID | AU1: Final consumption [FC] | AV1: Abb. | AW1: ID | AZ1: Resource [RS] | BA1: Abb. | BB1: ID | BE1: Year [YR] | BF1: ID | BG1: Duration | BH1: Number of years from the base year | BI1: Discount factor | BL1: Day [DY] | BM1: ID | BN1: Month | BR1: Weather [WE] | BS1: ID | BT1: Prob | BW1: Time [TM] | BX1: ID | CA1: Time zone ID | CB1: UTC zone
A2: Region [RG] | B2: =ROWS(ID_RG) -> 1 | F2: Export region | G2: EXP | H2: 0 | I2: 1 | J2: 1 | K2: 0 | N2: All | O2: ALL | P2: 1 | S2: Fuel cost | T2: FLC | U2: 0 | V2: G | W2: 0 | Z2: Direct Air Capture - Electricity (low temperature) | AA2: DACE1 | AB2: 0 | AC2: 2 | AF2: Direct Air Capture - Electricity (low temperature) | AG2: DACE1 | AH2: 0 | AK2: CO2 tanker | AL2: CXT | AM2: 0 | AP2: CO2 pipeline | AQ2: CXP | AR2: 0 | AU2: Fuel demand | AV2: SFF | AW2: 0 | AZ2: Hydro resource | BA2: HYR | BB2: 0 | BE2: YR2050 | BF2: 0 | BG2: 1 | BH2: 0 | BI2: 1 | BL2: DY1 | BM2: 0 | BN2: 0 | BR2: WR1 | BS2: 0 | BT2: 1 | BW2: TM1 | BX2: 0 | CA2: 0 | CB2: 0
A3: Item [IT] | B3: =ROWS(ID_IT) -> 49 | F3: Import region | G3: IMP | H3: =H2+1 -> 1 | I3: 1 | J3: 1 | K3: 0 | S3: Other variable cost | T3: OMC | U3: =U2+1 -> 1 | V3: G | W3: 0 | Z3: Direct Air Capture - Electricity (high temperature) | AA3: DACE2 | AB3: =AB2+1 -> 1 | AC3: 2 | AF3: Direct Air Capture - Electricity (high temperature) | AG3: DACE2 | AH3: =AH2+1 -> 1 | AK3: Methane gas tanker | AL3: LGT | AM3: =AM2+1 -> 1 | AP3: Methane gas pipeline | AQ3: NGP | AR3: =AR2+1 -> 1 | AZ3: Solar resource | BA3: SOR | BB3: =BB2+1 -> 1 | BL3: DY2 | BM3: =BM2+1 -> 1 | BN3: 0 | BW3: TM2 | BX3: =BX2+1 -> 1 | CA3: 1 | CB3: 9
A4: Activity [AC] | B4: =ROWS(ID_AC) -> 114 | S4: Saving penalty | T4: SVC | U4: =U3+1 -> 2 | V4: G | W4: 0 | Z4: CO2 liquefaction | AA4: CXL | AB4: =AB3+1 -> 2 | AC4: 2 | AF4: CO2 Liquefaction | AG4: CXL | AH4: =AH3+1 -> 2 | AK4: Hydrogen tanker | AL4: H2T | AM4: =AM3+1 -> 2 | AP4: Hydrogen pipeline | AQ4: H2P | AR4: =AR3+1 -> 2 | AZ4: Wind resource 1 (onshore) | BA4: WIR1 | BB4: =BB3+1 -> 2 | BE4: Discount rate | BL4: DY3 | BM4: =BM3+1 -> 2 | BN4: 0 | BW4: TM3 | BX4: =BX3+1 -> 2
A5: Nodal facility [NK] | B5: =ROWS(ID_NK) -> 50 | S5: Total electricity consumption | T5: TEC | U5: =U4+1 -> 3 | V5: N | W5: 2 | Z5: CO2 regasification | AA5: CXV | AB5: =AB4+1 -> 3 | AC5: 2 | AF5: Methane gas liquefaction | AG5: NGL | AH5: =AH4+1 -> 3 | AK5: Liquefied ammonia tanker | AL5: LAT | AM5: =AM4+1 -> 3 | AP5: HVAC line | AQ5: HVA | AR5: =AR4+1 -> 3 | AZ5: Wind resource 2 (offshore) | BA5: WIR2 | BB5: =BB4+1 -> 3 | BE5: 0.08 | BL5: DY4 | BM5: =BM4+1 -> 3 | BN5: 0 | BW5: TM4 | BX5: =BX4+1 -> 3
A6: Maritime trade facility [IK] | B6: =ROWS(ID_IK) -> 5 | S6: Emitted CO2 into atmosphere | T6: CO2 | U6: =U5+1 -> 4 | V6: N | W6: 0 | Z6: Methane gas liquefaction | AA6: NGL | AB6: =AB5+1 -> 4 | AC6: 2 | AF6: Methane gas rregasification | AG6: NGV | AH6: =AH5+1 -> 4 | AK6: MCH tanker | AL6: MCT | AM6: =AM5+1 -> 4 | AZ6: Fuel demand saving potential | BA6: SSV1 | BB6: =BB5+1 -> 4 | BL6: DY5 | BM6: =BM5+1 -> 4 | BN6: 0 | BW6: TM5 | BX6: =BX5+1 -> 4
A7: Land trade facility [IKL] | B7: =ROWS(ID_IKL) -> 4 | S7: CO2 emission from biomass-fired power plants | T7: CEPBD | U7: =U6+1 -> 5 | V7: G | W7: 2 | Z7: Methane gas regasification | AA7: NGV | AB7: =AB6+1 -> 5 | AC7: 2 | AF7: Methane storage | AG7: NGS | AH7: =AH6+1 -> 5 | BL7: DY6 | BM7: =BM6+1 -> 5 | BN7: 0 | BW7: TM6 | BX7: =BX6+1 -> 5
A8: Final consumption [FC] | B8: =ROWS(ID_FC) -> 1 | S8: CO2 recovered | T8: CRV | U8: =U7+1 -> 6 | V8: G | W8: 2 | Z8: Methane charge | AA8: NCH | AB8: =AB7+1 -> 6 | AC8: 2 | AF8: Methane storage tank | AG8: NGT | AH8: =AH7+1 -> 6 | BL8: DY7 | BM8: =BM7+1 -> 6 | BN8: 0 | BW8: TM7 | BX8: =BX7+1 -> 6
A9: Resource [RS] | B9: =ROWS(ID_RS) -> 5 | S9: Liquefied CO2 | T9: LCO | U9: =U8+1 -> 7 | V9: G | W9: 2 | Z9: Methane discharge | AA9: NDC | AB9: =AB8+1 -> 7 | AC9: 2 | AF9: Liquefied methane storage | AG9: LNGS | AH9: =AH8+1 -> 7 | BL9: DY8 | BM9: =BM8+1 -> 7 | BN9: 0 | BW9: TM8 | BX9: =BX8+1 -> 7
A10: Year [YR] | B10: =ROWS(ID_YR) -> 1 | S10: Methane | T10: MTN | U10: =U9+1 -> 8 | V10: E | W10: 2 | Z10: Methane charge/discharge activity | AA10: NSA | AB10: =AB9+1 -> 8 | AC10: 2 | AF10: Liquefied methane storage tank | AG10: LNGT | AH10: =AH9+1 -> 8 | BL10: DY9 | BM10: =BM9+1 -> 8 | BN10: 0 | BW10: TM9 | BX10: =BX9+1 -> 8
A11: Day [DY] | B11: =ROWS(ID_DY) -> 365 | S11: Methane storage | T11: NSE | U11: =U10+1 -> 9 | V11: E | W11: 2 | Z11: Methane storage at t-1 | AA11: NS1 | AB11: =AB10+1 -> 9 | AC11: 2 | AF11: Gas turbine power plant | AG11: GTG | AH11: =AH10+1 -> 9 | BL11: DY10 | BM11: =BM10+1 -> 9 | BN11: 0 | BW11: TM10 | BX11: =BX10+1 -> 9
A12: Month [MN] | B12: =MAX(ID_DM)+1 -> 37 | S12: Charge/discharge for CH4 storage | T12: NCD | U12: =U11+1 -> 10 | V12: E | W12: 2 | Z12: Methane storage at t | AA12: NS2 | AB12: =AB11+1 -> 10 | AC12: 2 | AF12: Hydro power plant | AG12: HYG | AH12: =AH11+1 -> 10 | BL12: DY11 | BM12: =BM11+1 -> 10 | BN12: 1 | BW12: TM11 | BX12: =BX11+1 -> 10
A13: Weather [WE] | B13: =ROWS(ID_WR) -> 1 | S13: Liquefied methane gas | T13: LNG | U13: =U12+1 -> 11 | V13: E | W13: 2 | Z13: Liquefied methane charge | AA13: LNCH | AB13: =AB12+1 -> 11 | AC13: 2 | AF13: Solar photovoltaics | AG13: SPG | AH13: =AH12+1 -> 11 | BL13: DY12 | BM13: =BM12+1 -> 11 | BN13: 1 | BW13: TM12 | BX13: =BX12+1 -> 11
A14: Time [TM] | B14: =ROWS(ID_TM) -> 24 | S14: Liquefied methane storage | T14: LNSE | U14: =U13+1 -> 12 | V14: E | W14: 2 | Z14: Liquefied methane discharge | AA14: LNDC | AB14: =AB13+1 -> 12 | AC14: 2 | AF14: Wind power 1 (onshore) | AG14: WIG1 | AH14: =AH13+1 -> 12 | BL14: DY13 | BM14: =BM13+1 -> 12 | BN14: 1 | BW14: TM13 | BX14: =BX13+1 -> 12
A15: Time zone [TZD] | B15: =ROWS(ID_TZD) -> 2 | S15: Charge/discharge for LCH4 storage | T15: LNCD | U15: =U14+1 -> 13 | V15: E | W15: 2 | Z15: Liquefied methane charge/discharge activity | AA15: LNSA | AB15: =AB14+1 -> 13 | AC15: 2 | AF15: Wind power 2 (offshore) | AG15: WIG2 | AH15: =AH14+1 -> 13 | BL15: DY14 | BM15: =BM14+1 -> 13 | BN15: 1 | BW15: TM14 | BX15: =BX14+1 -> 13
A16: # of item 2 | B16: =COUNTIF(ID_ITM,2) -> 33 | S16: Liquefied methane gas (loaded on the tanker) | T16: LNG2 | U16: =U15+1 -> 14 | V16: E | W16: 0 | Z16: Liquefied methane storage at t-1 | AA16: LNS1 | AB16: =AB15+1 -> 14 | AC16: 2 | AF16: Biomass direct fired power plant | AG16: BDG | AH16: =AH15+1 -> 14 | BL16: DY15 | BM16: =BM15+1 -> 14 | BN16: 1 | BW16: TM15 | BX16: =BX15+1 -> 14
A17: # of activity 2 | B17: =COUNTIF(ID_ACM,2) -> 94 | S17: Hydro power resource | T17: HYR | U17: =U16+1 -> 15 | V17: G | W17: 0 | Z17: Liquefied methane storage at t | AA17: LNS2 | AB17: =AB16+1 -> 15 | AC17: 2 | AF17: Light water reactor | AG17: LWR | AH17: =AH16+1 -> 15 | BL17: DY16 | BM17: =BM16+1 -> 15 | BN17: 1 | BW17: TM16 | BX17: =BX16+1 -> 15
A18: Output file column1 | B18: =SUBSTITUTE(ADDRESS(1,B10*(B56+B3)+1,4),"1","") -> BJ | S18: Solar power resource | T18: SOR | U18: =U17+1 -> 16 | V18: G | W18: 0 | Z18: Liquefied methane loading | AA18: LNLD | AB18: =AB17+1 -> 16 | AC18: 2 | AF18: Battery storage 1 | AG18: PPS | AH18: =AH17+1 -> 16 | BL18: DY17 | BM18: =BM17+1 -> 16 | BN18: 1 | BW18: TM17 | BX18: =BX17+1 -> 16
A19: Output file column2 | B19: =SUBSTITUTE(ADDRESS(1,B11*B13*B14+2,4),"1","") -> LXZ | S19: Wind power resource 1 (onshore) | T19: WIR1 | U19: =U18+1 -> 17 | V19: G | W19: 0 | Z19: Liquefied methane unloading | AA19: LNUL | AB19: =AB18+1 -> 17 | AC19: 2 | AF19: Battery storage 2 | AG19: BTSS | AH19: =AH18+1 -> 17 | BL19: DY18 | BM19: =BM18+1 -> 17 | BN19: 1 | BW19: TM18 | BX19: =BX18+1 -> 17
S20: Wind power resource 2 (offshore) | T20: WIR2 | U20: =U19+1 -> 18 | V20: G | W20: 0 | Z20: Grid electricity procurement | AA20: GELP | AB20: =AB19+1 -> 18 | AC20: 2 | AF20: Battery storage 3 | AG20: BTSL | AH20: =AH19+1 -> 18 | BL20: DY19 | BM20: =BM19+1 -> 18 | BN20: 1 | BW20: TM19 | BX20: =BX19+1 -> 18
S21: Biomass for direct fired power and/or heat generation | T21: BDG | U21: =U20+1 -> 19 | V21: G | W21: 0 | Z21: Natural gas procurement | AA21: NGSP | AB21: =AB20+1 -> 19 | AC21: 2 | AF21: Electrolyzer | AG21: WEL | AH21: =AH20+1 -> 19 | BL21: DY20 | BM21: =BM20+1 -> 19 | BN21: 1 | BW21: TM20 | BX21: =BX20+1 -> 19
S22: Electricity | T22: ELC | U22: =U21+1 -> 20 | V22: E | W22: 2 | Z22: Fuel oil procurement (for seaborne transportation) | AA22: FOLP | AB22: =AB21+1 -> 20 | AC22: 0 | AF22: Hydrogen storage | AG22: H2S | AH22: =AH21+1 -> 20 | BL22: DY21 | BM22: =BM21+1 -> 20 | BN22: 2 | BW22: TM21 | BX22: =BX21+1 -> 20
A23: Carbon content [t-C/toe] | S23: Stored electricity at battery 1 | T23: PSE | U23: =U22+1 -> 21 | V23: E | W23: 2 | Z23: Ammonia procurement (for seaborne transportation) | AA23: AMMP | AB23: =AB22+1 -> 21 | AC23: 0 | AF23: Hydrogen storage tank | AG23: H2T | AH23: =AH22+1 -> 21 | BL23: DY22 | BM23: =BM22+1 -> 21 | BN23: 2 | BW23: TM22 | BX23: =BX22+1 -> 21
A24: Coal | B24: 1.0802 | S24: Charge/discharge at battery 1 | T24: PCD | U24: =U23+1 -> 22 | V24: E | W24: 2 | Z24: Gas turbine power generation | AA24: GTG | AB24: =AB23+1 -> 22 | AC24: 2 | AF24: Liquefied hydrogen storage | AG24: LH2S | AH24: =AH23+1 -> 22 | BL24: DY23 | BM24: =BM23+1 -> 22 | BN24: 2 | BW24: TM23 | BX24: =BX23+1 -> 22
A25: Methane | B25: 0.6406 | S25: Stored electricity at battery 2 | T25: BSES | U25: =U24+1 -> 23 | V25: E | W25: 2 | Z25: Hydro power generation | AA25: HYG | AB25: =AB24+1 -> 23 | AC25: 2 | AF25: Liquefied hydrogen storage tank | AG25: LH2T | AH25: =AH24+1 -> 23 | BL25: DY24 | BM25: =BM24+1 -> 23 | BN25: 2 | BW25: TM24 | BX25: =BX24+1 -> 23
A26: Crude oil | B26: 0.8374 | S26: Charge/discharge at battery 2 | T26: BCDS | U26: =U25+1 -> 24 | V26: E | W26: 2 | Z26: Suppressed hydro | AA26: HYD | AB26: =AB25+1 -> 24 | AC26: 2 | AF26: Hydrogen Liquefaction | AG26: H2L | AH26: =AH25+1 -> 24 | BL26: DY25 | BM26: =BM25+1 -> 24 | BN26: 2
A27: Gasoline | B27: =69.3*12/44/0.0000238845897/10^6 -> 0.7913052 | S27: Stored electricity at battery 3 | T27: BSEL | U27: =U26+1 -> 25 | V27: E | W27: 2 | Z27: Solar photovoltaics power generation | AA27: SPG | AB27: =AB26+1 -> 25 | AC27: 2 | AF27: Hydrogen Regasification | AG27: H2V | AH27: =AH26+1 -> 25 | BL27: DY26 | BM27: =BM26+1 -> 25 | BN27: 2
A28: Diesel | B28: =67.8*12/44/0.0000238845897/10^6 -> 0.77417738 | S28: Charge/discharge at battery 3 | T28: BCDL | U28: =U27+1 -> 26 | V28: E | W28: 2 | Z28: Suppressed PV | AA28: SPD | AB28: =AB27+1 -> 26 | AC28: 2 | AF28: Methane synthesis | AG28: MTS | AH28: =AH27+1 -> 26 | BL28: DY27 | BM28: =BM27+1 -> 26 | BN28: 2
A29: Other oil products | S29: Non-synchronous electricity | T29: NSC | U29: =U28+1 -> 27 | V29: CL | W29: 2 | Z29: Wind power generation 1 (onshore) | AA29: WIG1 | AB29: =AB28+1 -> 27 | AC29: 2 | AF29: Methane synthesis 2 - high efficiency | AG29: MTS2 | AH29: =AH28+1 -> 27 | BL29: DY28 | BM29: =BM28+1 -> 27 | BN29: 2
A30: Biomass | B30: 1.124 | S30: Hydrogen | T30: HYN | U30: =U29+1 -> 28 | V30: E | W30: 2 | Z30: Wind power generation 2 (offshore) | AA30: WIG2 | AB30: =AB29+1 -> 28 | AC30: 2 | AF30: Ammonia synthesis | AG30: AMS | AH30: =AH29+1 -> 28 | BL30: DY29 | BM30: =BM29+1 -> 28 | BN30: 2
A31: Methanol | B31: 0.7866 | S31: Liquefied hydrogen | T31: LHY | U31: =U30+1 -> 29 | V31: E | W31: 2 | Z31: Suppressed wind 1 | AA31: WID1 | AB31: =AB30+1 -> 29 | AC31: 2 | AF31: Hydrogen separation | AG31: HSP | AH31: =AH30+1 -> 29 | BL31: DY30 | BM31: =BM30+1 -> 29 | BN31: 2
S32: Liquefied hydrogen (loaded on the tanker) | T32: LHY2 | U32: =U31+1 -> 30 | V32: E | W32: 0 | Z32: Suppressed wind 2 | AA32: WID2 | AB32: =AB31+1 -> 30 | AC32: 2 | AF32: Ammonia storage | AG32: AMMS | AH32: =AH31+1 -> 30 | BL32: DY31 | BM32: =BM31+1 -> 30 | BN32: 3
S33: Hydrogen storage | T33: HSE | U33: =U32+1 -> 31 | V33: E | W33: 2 | Z33: Biomass direct fired power generation | AA33: BDG | AB33: =AB32+1 -> 31 | AC33: 2 | AF33: Ammonia storage tank | AG33: AMMT | AH33: =AH32+1 -> 31 | BL33: DY32 | BM33: =BM32+1 -> 31 | BN33: 3
A34: Case | S34: Charge/discharge for H2 storage | T34: HCD | U34: =U33+1 -> 32 | V34: E | W34: 2 | Z34: Light water reactor power generation | AA34: LWR | AB34: =AB33+1 -> 32 | AC34: 2 | AF34: Hydrogenation of toluene | AG34: MCS | AH34: =AH33+1 -> 32 | BL34: DY33 | BM34: =BM33+1 -> 32 | BN34: 3
A35: Max. share of non-synchronous generation | S35: LH2 storage | T35: LHSE | U35: =U34+1 -> 33 | V35: E | W35: 2 | Z35: Battery charge 1 | AA35: PCH | AB35: =AB34+1 -> 33 | AC35: 2 | AF35: Dehydrogenation (MCH) | AG35: DHG | AH35: =AH34+1 -> 33 | BL35: DY34 | BM35: =BM34+1 -> 33 | BN35: 3
A36: PV+Wind+NetImp(DC)+NetDcha | S36: Charge/discharge for LH2 storage | T36: LHCD | U36: =U35+1 -> 34 | V36: E | W36: 2 | Z36: Battery discharge 1 | AA36: PDC | AB36: =AB35+1 -> 34 | AC36: 2 | AF36: MCH storage | AG36: MCHS | AH36: =AH35+1 -> 34 | BL36: DY35 | BM36: =BM35+1 -> 34 | BN36: 3
A37: ="no constraint=-1" -> no constraint=-1 | B37: -1 | S37: Ammonia | T37: AMM | U37: =U36+1 -> 35 | V37: E | W37: 2 | Z37: Battery 1 charge/discharge activity | AA37: PSA | AB37: =AB36+1 -> 35 | AC37: 2 | AF37: MCH storage tank | AG37: MCHT | AH37: =AH36+1 -> 35 | BL37: DY36 | BM37: =BM36+1 -> 35 | BN37: 3
S38: Ammonia (loaded on the tanker) | T38: AMM2 | U38: =U37+1 -> 36 | V38: E | W38: 0 | Z38: Battery 1 storage at t-1 | AA38: PS1 | AB38: =AB37+1 -> 36 | AC38: 2 | AF38: Gas boiler | AG38: GBL | AH38: =AH37+1 -> 36 | BL38: DY37 | BM38: =BM37+1 -> 36 | BN38: 3
S39: Ammonia storage | T39: AMSE | U39: =U38+1 -> 37 | V39: E | W39: 2 | Z39: Battery 1 storage at t | AA39: PS2 | AB39: =AB38+1 -> 37 | AC39: 2 | AF39: Ammonia boiler | AG39: ABL | AH39: =AH38+1 -> 37 | BL39: DY38 | BM39: =BM38+1 -> 37 | BN39: 3
S40: Charge/discharge for NH3 storage | T40: AMCD | U40: =U39+1 -> 38 | V40: E | W40: 2 | Z40: Battery 2 charge | AA40: BCHS | AB40: =AB39+1 -> 38 | AC40: 2 | AF40: Hydrogen boiler | AG40: HBL | AH40: =AH39+1 -> 38 | BL40: DY39 | BM40: =BM39+1 -> 38 | BN40: 3
...

Sheet RG
A1: =IND!A2 -> Region [RG] | B1: RGD | C1: 1
A2: =ROWS(RGD) -> 2 | B2: =COLUMNS(RGD) -> 1 | C2: =INDEX(ID_RG,C1) -> ALL | D2: For IK_DK sheet
A3: 1 | B3: =INDEX(ID_ND,A3) -> EXP | C3: 1 | D3: =IFERROR(MATCH(1,C3:C3),"") -> 1
A4: =A3+1 -> 2 | B4: =INDEX(ID_ND,A4) -> IMP | C4: 1 | D4: =IFERROR(MATCH(1,C4:C4),"") -> 1

Sheet EMI
A1: Emission constraint [RGE] | D1: 1 | I1: Carbon price [Ctax] $/t-C
A2: =ROWS(RGE_D) -> 1 | B2: =COLUMNS(RGE_D) -> 1 | D2: =INDEX(ID_YR,D1) -> YR2050 | K2: =D2 -> YR2050
A3: 1 | B3: Case 1 | C3: =INDEX(ID_RG,A3) -> ALL | D3: =IF(CASE!C13=-1,-1,CASE!C13) -> 0 | I3: =B3 -> Case 1 | J3: =C3 -> ALL | K3: -1
Q66: YR2070
Q67: =#REF!+(#REF!-#REF!) -> #REF!
Q68: =#REF!*Q67/#REF! -> #REF!
Q69: =Q67-Q68 -> #REF!
Q70: =#REF!+(#REF!-#REF!) -> #REF!
Q71: =Q69+Q70 -> #REF!
Q72: =#REF!*Q71/#REF! -> #REF!
Q73: =Q70-Q72 -> #REF!

Sheet AC
B1: Row | C1: Column | F1: =IND!A4 -> Activity [AC] | H1: DACE1 | I1: DACE2 | J1: CXL | K1: CXV | L1: NGL | M1: NGV | N1: NCH | O1: NDC | P1: NSA | Q1: NS1 | R1: NS2 | S1: LNCH | T1: LNDC | U1: LNSA | V1: LNS1 | W1: LNS2 | X1: LNLD | Y1: LNUL | Z1: GELP | AA1: NGSP | AB1: FOLP | AC1: AMMP | AD1: GTG | AE1: HYG | AF1: HYD | AG1: SPG | AH1: SPD | AI1: WIG1 | AJ1: WIG2 | AK1: WID1 | AL1: WID2 | AM1: BDG | AN1: LWR | AO1: PCH | AP1: PDC | AQ1: PSA | AR1: PS1 | AS1: PS2 | AT1: BCHS | AU1: BDCS | AV1: BSAS | AW1: BS1S | AX1: BS2S | AY1: BCHL | AZ1: BDCL | BA1: BSAL | BB1: BS1L | BC1: BS2L | BD1: WEL | BE1: HCH | BF1: HDC | BG1: HSA | BH1: HS1 | BI1: HS2 | BJ1: LHCH | BK1: LHDC | BL1: LHSA | BM1: LHS1 | BN1: LHS2 | BO1: H2L | BP1: H2V | BQ1: LHLD | BR1: LHUL | BS1: MTS | BT1: MTS2 | BU1: AMS | BV1: HSP | BW1: AMCH | BX1: AMDC | BY1: AMSA | BZ1: AMS1 | CA1: AMS2 | CB1: AMLD | CC1: AMUL | CD1: MCS | CE1: DHG | CF1: MCCH | CG1: MCDC | CH1: MCSA | CI1: MCS1 | CJ1: MCS2 | CK1: MCLD | CL1: MCUL | CM1: GBL | CN1: ABL | CO1: HBL | CP1: HPP | CQ1: SSV | CR1: SSV1 | CS1: NGF | CT1: H2F | CU1: AMF | CV1: CX_IS | CW1: CX_ES | CX1: CX_IL | CY1: CX_EL | CZ1: NG_IS | DA1: NG_ES | DB1: NG_IL | DC1: NG_EL | DD1: H2_IS | DE1: H2_ES | DF1: H2_IL | DG1: H2_EL | DH1: LA_IS | DI1: LA_ES | DJ1: MC_IS | DK1: MC_ES | DL1: EL_IA | DM1: EL_EA | DN1: CX_SLS | DO1: CX_LLS | DP1: NG_SLS | DQ1: NG_LLS
A2: ACI | B2: =ROWS(ACI) -> 1 | C2: =COLUMNS(ACI) -> 114 | F2: ID | H2: =MATCH(H1,ID_AC,0)-1 -> 0 | I2: =MATCH(I1,ID_AC,0)-1 -> 1 | J2: =MATCH(J1,ID_AC,0)-1 -> 2 | K2: =MATCH(K1,ID_AC,0)-1 -> 3 | L2: =MATCH(L1,ID_AC,0)-1 -> 4 | M2: =MATCH(M1,ID_AC,0)-1 -> 5 | N2: =MATCH(N1,ID_AC,0)-1 -> 6 | O2: =MATCH(O1,ID_AC,0)-1 -> 7 | ... DQ2: =MATCH(DQ1,ID_AC,0)-1 -> 113
A3: ACF | B3: =ROWS(ACF) -> 11 | C3: =COLUMNS(ACF) -> 114 | F3: Base | AM3: ELC | BD3: ELC
A4: ACD_1 | B4: =ROWS(ACD_1) -> 8 | C4: =COLUMNS(ACD_1) -> 114 | F4: 0 | H4: CRV | I4: CRV | J4: ELC | K4: CRV | L4: MTN | M4: MTN | N4: MTN | O4: MTN | P4: NCD | Q4: NSE | R4: NSE | S4: LNG | T4: LNG | U4: LNCD | V4: LNSE | W4: LNSE | X4: LNG | Y4: LNG | Z4: ELC | AA4: MTN | AB4: FLC | AC4: AMM | AD4: MTN | AE4: ELC | AF4: HYR | AG4: ELC | AH4: SOR | AI4: ELC | AJ4: ELC | AK4: WIR1 | AL4: WIR2 | AM4: BDG | AN4: ELC | AO4: ELC | AP4: ELC | AQ4: PCD | AR4: PSE | AS4: PSE | AT4: ELC | AU4: ELC | AV4: BCDS | AW4: BSES | AX4: BSES | AY4: ELC | AZ4: ELC | BA4: BCDL | BB4: BSEL | BC4: BSEL | BD4: ELC | BE4: HYN | BF4: HYN | BG4: HCD | BH4: HSE | BI4: HSE | BJ4: LHY | BK4: LHY | BL4: LHCD | BM4: LHSE | BN4: LHSE | BO4: HYN | BP4: HYN | BQ4: LHY | BR4: LHY | BS4: MTN | BT4: MTN | BU4: AMM | BV4: ELC | BW4: AMM | BX4: AMM | BY4: AMCD | BZ4: AMSE | CA4: AMSE | CB4: AMM | CC4: AMM | CD4: ELC | CE4: HYN | CF4: MCH | CG4: MCH | CH4: MCCD | CI4: MCSE | CJ4: MCSE | CK4: MCH | CL4: MCH | CM4: MTN | CN4: AMM | CO4: HYN | CP4: ELC | CQ4: SFF | CR4: SSV1 | CS4: MTN | CT4: HYN | CU4: AMM | CV4: LCO | CW4: LCO | CX4: CRV | CY4: CRV | CZ4: LNG2 | DA4: LNG2 | DB4: MTN | DC4: MTN | DD4: LHY2 | DE4: LHY2 | DF4: HYN | DG4: HYN | DH4: AMM2 | DI4: AMM2 | DJ4: MCH2 | DK4: MCH2 | DL4: ELC | DM4: ELC | DN4: CO2 | DO4: CO2 | DP4: CO2 | DQ4: CO2
A5: ACD_2 | B5: =ROWS(ACD_2) -> 1 | C5: =COLUMNS(ACD_2) -> 114 | F5: 1 | H5: LTH | I5: ELC | J5: CRV | K5: LCO | L5: LNG | M5: LNG | N5: NSE | O5: NSE | S5: LNSE | T5: LNSE | X5: LNG2 | Y5: LNG2 | AA5: CO2 | AB5: FSBT | AC5: FSBT | AD5: ELC | AE5: HYR | AG5: SOR | AI5: WIR1 | AJ5: WIR2 | AM5: CEPBD | AN5: FLC | AO5: PSE | AP5: PSE | AT5: BSES | AU5: BSES | AY5: BSEL | AZ5: BSEL | BD5: HYN | BE5: HSE | BF5: HSE | BJ5: LHSE | BK5: LHSE | BO5: LHY | BP5: LHY | BQ5: LHY2 | BR5: LHY2 | BS5: HYN | BT5: CRV | BU5: HYN | BV5: HYN | BW5: AMSE | BX5: AMSE | CB5: AMM2 | CC5: AMM2 | CD5: TEC | CE5: MCH | CF5: MCSE | CG5: MCSE | CK5: MCH2 | CL5: MCH2 | CM5: HEA | CN5: HEA | CO5: HEA | CP5: LTH | CS5: SFF | CT5: SFF | CU5: SFF | CV5: CO2 | CW5: CO2 | CX5: CO2 | CY5: CO2 | CZ5: CO2 | DA5: CO2 | DB5: CO2 | DC5: CO2 | DK5: FSBT | DL5: TEC | DM5: TEC
A6: ACD_3 | B6: =ROWS(ACD_3) -> 2 | C6: =COLUMNS(ACD_3) -> 114 | F6: 2 | H6: ELC | I6: TEC | J6: LCO | L6: ELC | M6: ELC | N6: NCD | O6: NCD | S6: LNCD | T6: LNCD | AB6: CO2 | AG6: NSC | AI6: NSC | AJ6: NSC | AM6: ELC | AO6: PCD | AP6: PCD | AT6: BCDS | AU6: BCDS | AY6: BCDL | AZ6: BCDL | BD6: NSC | BE6: HCD | BF6: HCD | BJ6: LHCD | BK6: LHCD | BO6: ELC | BS6: CRV | BT6: ELC | BU6: ELC | BV6: AMM | BW6: AMCD | BX6: AMCD | CD6: HEA | CE6: ELC | CF6: MCCD | CG6: MCCD | CV6: OMC | CW6: OMC
A7: Battery 1 - stored energy | B7: =MATCH("PS1",ID_AC,0)-1 -> 36 | C7: =MATCH("PS2",ID_AC,0)-1 -> 37 | F7: 3 | H7: TEC | J7: TEC | L7: OMC | M7: OMC | N7: ELC | S7: ELC | AO7: OMC | AT7: OMC | AU7: NSC | AY7: OMC | AZ7: NSC | BD7: TEC | BE7: ELC | BJ7: ELC | BK7: ELC | BO7: TEC | BS7: ELC | BT7: TEC | BU7: TEC | BV7: HEA | BW7: ELC | BX7: ELC | CD7: HYN | CE7: HEA | CF7: ELC | CG7: ELC
A8: Battery 2 - stored energy | B8: =MATCH("BS1S",ID_AC,0)-1 -> 41 | C8: =MATCH("BS2S",ID_AC,0)-1 -> 42 | F8: 4 | L8: TEC | M8: TEC | N8: TEC | S8: TEC | AO8: NSC | AT8: NSC | AY8: NSC | BD8: OMC | BE8: TEC | BJ8: TEC | BK8: TEC | BS8: TEC | BT8: OMC | BV8: TEC | BW8: TEC | BX8: TEC | CD8: MCH | CE8: TEC | CF8: TEC | CG8: TEC
A9: Battery 3 - stored energy | B9: =MATCH("BS1L",ID_AC,0)-1 -> 46 | C9: =MATCH("BS2L",ID_AC,0)-1 -> 47 | F9: 5 | CD9: OMC
A10: Hydrogen - stored energy | B10: =MATCH("HS1",ID_AC,0)-1 -> 52 | C10: =MATCH("HS2",ID_AC,0)-1 -> 53 | F10: 6
A11: Liquefied hydrogen - stored energy | B11: =MATCH("LHS1",ID_AC,0)-1 -> 57 | C11: =MATCH("LHS2",ID_AC,0)-1 -> 58 | F11: 7
A12: Methane - stored energy | B12: =MATCH("NS1",ID_AC,0)-1 -> 9 | C12: =MATCH("NS2",ID_AC,0)-1 -> 10 | F12: 10
A13: Liquefied methane - stored energy | B13: =MATCH("LNS1",ID_AC,0)-1 -> 14 | C13: =MATCH("LNS2",ID_AC,0)-1 -> 15 | F13: 20 | Z13: OMC | AA13: FLC | CR13: SVC
A14: MCH - stored energy | B14: =MATCH("MCS1",ID_AC,0)-1 -> 79 | C14: =MATCH("MCS2",ID_AC,0)-1 -> 80 | F14: Unit | H14: Mt-C | I14: Mt-C | J14: TWh/Mt-C | K14: Mt-C | L14: Mtoe | M14: Mtoe | N14: Mtoe | O14: Mtoe | P14: Mtoe | Q14: Mtoe | R14: Mtoe | S14: Mtoe | T14: Mtoe | U14: Mtoe | V14: Mtoe | W14: Mtoe | X14: Mtoe | Y14: Mtoe | Z14: TWh | AA14: Mtoe | AB14: M$/Mtoe | AC14: Mtoe | AD14: Mtoe | AE14: TWh | AF14: TWh | AG14: TWh | AH14: TWh | AI14: TWh | AJ14: TWh | AK14: TWh | AL14: TWh | AM14: Mtoe | AN14: TWh | AO14: TWh | AP14: TWh | AQ14: TWh | AR14: TWh | AS14: TWh | AT14: TWh | AU14: TWh | AV14: TWh | AW14: TWh | AX14: TWh | AY14: TWh | AZ14: TWh | BA14: TWh | BB14: TWh | BC14: TWh | BD14: TWh | BE14: Mtoe | BF14: Mtoe | BG14: Mtoe | BH14: Mtoe | BI14: Mtoe | BJ14: Mtoe | BK14: Mtoe | BL14: Mtoe | BM14: Mtoe | BN14: Mtoe | BO14: Mtoe | BP14: Mtoe | BQ14: Mtoe | BR14: Mtoe | BS14: Mtoe | BT14: Mtoe | BU14: Mtoe | BV14: TWh | BW14: Mtoe | BX14: Mtoe | BY14: Mtoe | BZ14: Mtoe | CA14: Mtoe | CB14: Mtoe | CC14: Mtoe | CD14: TWh | CE14: Mtoe | CF14: Mton-MCH | CG14: Mton-MCH | CH14: Mton-MCH | CI14: Mton-MCH | CJ14: Mton-MCH | CK14: Mton | CL14: Mton | CM14: Mtoe | CN14: Mtoe | CO14: Mtoe | CP14: TWh | CQ14: Mtoe | CR14: Mtoe | CS14: Mtoe | CT14: Mtoe | CU14: Mtoe | CV14: Mt-C | CW14: Mt-C | CX14: Mt-C | CY14: Mt-C | CZ14: Mtoe | DA14: Mtoe | DB14: Mtoe | DC14: Mtoe | DD14: Mtoe | DE14: Mtoe | DF14: Mtoe | DG14: Mtoe | DH14: Mtoe | DI14: Mtoe | DJ14: Mton | DK14: Mton | DL14: TWh | DM14: TWh | DN14: Mt-C/Mtoe | DO14: Mt-C/Mtoe | DP14: Mt-C/Mtoe | DQ14: Mt-C/Mtoe
A15: Ammonia - stored energy | B15: =MATCH("AMS1",ID_AC,0)-1 -> 70 | C15: =MATCH("AMS2",ID_AC,0)-1 -> 71 | F15: =F5 -> 1 | H15: TWh/Mt-C | I15: TWh/Mt-C | J15: Mt-C | K15: Mt-C | L15: Mtoe | M15: Mtoe | N15: Mtoe | O15: Mtoe | S15: Mtoe | T15: Mtoe | X15: Mtoe | Y15: Mtoe | AA15: Mt-C/Mtoe | AB15: Mtoe | AC15: Mtoe | AD15: TWh | AE15: TWh | AG15: TWh | AI15: TWh | AJ15: TWh | AM15: t-C/Mtoe | AN15: M$/TWh | AO15: TWh | AP15: TWh | AT15: TWh | AU15: TWh | AY15: TWh | AZ15: TWh | BD15: Mtoe | BE15: Mtoe | BF15: Mtoe | BJ15: Mtoe | BK15: Mtoe | BO15: Mtoe | BP15: Mtoe | BQ15: Mtoe | BR15: Mtoe | BS15: Mtoe | BT15: Mt-C | BU15: Mtoe | BV15: Mtoe | BW15: Mtoe | BX15: Mtoe | CB15: Mtoe | CC15: Mtoe | CD15: TWh | CE15: Mton-MCH | CF15: Mton-MCH | CG15: Mton-MCH | CK15: Mton | CL15: Mton | CM15: Mtoe | CN15: Mtoe | CO15: Mtoe | CP15: TWh | CS15: Mtoe | CT15: Mtoe | CU15: Mtoe | CV15: Mt-C | CW15: Mt-C | CX15: Mt-C | CY15: Mt-C | CZ15: Mt-C/Mtoe | DA15: Mt-C/Mtoe | DB15: Mt-C/Mtoe | DC15: Mt-C/Mtoe | DK15: Mtoe | DL15: TWh | DM15: TWh
F16: =F6 -> 2 | H16: TWh/Mt-C | I16: TWh/Mt-C | J16: Mt-C | L16: TWh/Mtoe | M16: M$/Mtoe | N16: Mtoe | O16: Mtoe | S16: Mtoe | T16: Mtoe | AB16: MtC/Mtoe | AG16: TWh | AI16: TWh | AJ16: TWh | AM16: TWh | AO16: TWh | AP16: TWh | AT16: TWh | AU16: TWh | AY16: TWh | AZ16: TWh | BD16: TWh | BE16: Mtoe | BF16: Mtoe | BJ16: Mtoe | BK16: Mtoe | BO16: TWh/Mtoe | BS16: Mt-C | BT16: TWh/Mtoe | BU16: TWh/Mtoe | BV16: Mtoe | BW16: Mtoe | BX16: Mtoe | CD16: Mtoe | CE16: TWh | CF16: Mton-MCH | CG16: Mton-MCH | CV16: M$/Mt-C | CW16: M$/Mt-C
F17: =F7 -> 3 | H17: TWh/Mt-C | J17: TWh/Mt-C | L17: M$/Mtoe | N17: TWh | S17: TWh | AO17: M$/TWh | AT17: M$/TWh | AU17: TWh | AY17: M$/TWh | AZ17: TWh | BD17: TWh | BE17: TWh | BJ17: TWh | BK17: TWh | BO17: TWh/Mtoe | BS17: TWh/Mtoe | BT17: TWh/Mtoe | BU17: TWh/Mtoe | BV17: Mtoe | BW17: TWh | BX17: TWh | CD17: Mtoe | CE17: Mtoe | CF17: TWh | CG17: TWh
F18: =F8 -> 4 | L18: TWh/Mtoe | N18: TWh | S18: TWh | AO18: TWh | AT18: TWh | AY18: TWh | BD18: M$/Mtoe | BE18: TWh | BJ18: TWh | BK18: TWh | BS18: TWh/Mtoe | BT18: M$/Mtoe | BV18: TWh | BW18: TWh | BX18: TWh | CD18: Mton-MCH | CF18: TWh | CG18: TWh
F19: =F9 -> 5 | CD19: M$/Mtoe
F20: =F10 -> 6
F21: =F11 -> 7
F22: 10
F23: =F13 -> 20 | Z23: M$/TWh | CR23: M$/Mtoe
F24: =F3 -> Base | G24: =COUNTA(H4:DQ13) -> 271 | H24: =IF(H3="",-1,MATCH(H3,ID_IT,0)-1) -> -1 | I24: =IF(I3="",-1,MATCH(I3,ID_IT,0)-1) -> -1 | J24: =IF(J3="",-1,MATCH(J3,ID_IT,0)-1) -> -1 | K24: =IF(K3="",-1,MATCH(K3,ID_IT,0)-1) -> -1 | L24: =IF(L3="",-1,MATCH(L3,ID_IT,0)-1) -> -1 | M24: =IF(M3="",-1,MATCH(M3,ID_IT,0)-1) -> -1 | N24: =IF(N3="",-1,MATCH(N3,ID_IT,0)-1) -> -1 | O24: =IF(O3="",-1,MATCH(O3,ID_IT,0)-1) -> -1 | ... DQ24: =IF(DQ3="",-1,MATCH(DQ3,ID_IT,0)-1) -> -1
F25: =F4 -> 0 | H25: =IF(H4="",-1,MATCH(H4,ID_IT,0)-1) -> 6 | I25: =IF(I4="",-1,MATCH(I4,ID_IT,0)-1) -> 6 | J25: =IF(J4="",-1,MATCH(J4,ID_IT,0)-1) -> 20 | K25: =IF(K4="",-1,MATCH(K4,ID_IT,0)-1) -> 6 | L25: =IF(L4="",-1,MATCH(L4,ID_IT,0)-1) -> 8 | M25: =IF(M4="",-1,MATCH(M4,ID_IT,0)-1) -> 8 | N25: =IF(N4="",-1,MATCH(N4,ID_IT,0)-1) -> 8 | O25: =IF(O4="",-1,MATCH(O4,ID_IT,0)-1) -> 8 | ... DQ25: =IF(DQ4="",-1,MATCH(DQ4,ID_IT,0)-1) -> 4
F26: =F5 -> 1 | H26: =IF(H5="",-1,MATCH(H5,ID_IT,0)-1) -> 45 | I26: =IF(I5="",-1,MATCH(I5,ID_IT,0)-1) -> 20 | J26: =IF(J5="",-1,MATCH(J5,ID_IT,0)-1) -> 6 | K26: =IF(K5="",-1,MATCH(K5,ID_IT,0)-1) -> 7 | L26: =IF(L5="",-1,MATCH(L5,ID_IT,0)-1) -> 11 | M26: =IF(M5="",-1,MATCH(M5,ID_IT,0)-1) -> 11 | N26: =IF(N5="",-1,MATCH(N5,ID_IT,0)-1) -> 9 | O26: =IF(O5="",-1,MATCH(O5,ID_IT,0)-1) -> 9 | ... DQ26: =IF(DQ5="",-1,MATCH(DQ5,ID_IT,0)-1) -> -1
F27: =F6 -> 2 | H27: =IF(H6="",-1,MATCH(H6,ID_IT,0)-1) -> 20 | I27: =IF(I6="",-1,MATCH(I6,ID_IT,0)-1) -> 3 | J27: =IF(J6="",-1,MATCH(J6,ID_IT,0)-1) -> 7 | K27: =IF(K6="",-1,MATCH(K6,ID_IT,0)-1) -> -1 | L27: =IF(L6="",-1,MATCH(L6,ID_IT,0)-1) -> 20 | M27: =IF(M6="",-1,MATCH(M6,ID_IT,0)-1) -> 20 | N27: =IF(N6="",-1,MATCH(N6,ID_IT,0)-1) -> 10 | O27: =IF(O6="",-1,MATCH(O6,ID_IT,0)-1) -> 10 | ... DQ27: =IF(DQ6="",-1,MATCH(DQ6,ID_IT,0)-1) -> -1
F28: =F7 -> 3 | H28: =IF(H7="",-1,MATCH(H7,ID_IT,0)-1) -> 3 | I28: =IF(I7="",-1,MATCH(I7,ID_IT,0)-1) -> -1 | J28: =IF(J7="",-1,MATCH(J7,ID_IT,0)-1) -> 3 | K28: =IF(K7="",-1,MATCH(K7,ID_IT,0)-1) -> -1 | L28: =IF(L7="",-1,MATCH(L7,ID_IT,0)-1) -> 1 | M28: =IF(M7="",-1,MATCH(M7,ID_IT,0)-1) -> 1 | N28: =IF(N7="",-1,MATCH(N7,ID_IT,0)-1) -> 20 | O28: =IF(O7="",-1,MATCH(O7,ID_IT,0)-1) -> -1 | ... DQ28: =IF(DQ7="",-1,MATCH(DQ7,ID_IT,0)-1) -> -1
F29: =F8 -> 4 | H29: =IF(H8="",-1,MATCH(H8,ID_IT,0)-1) -> -1 | I29: =IF(I8="",-1,MATCH(I8,ID_IT,0)-1) -> -1 | J29: =IF(J8="",-1,MATCH(J8,ID_IT,0)-1) -> -1 | K29: =IF(K8="",-1,MATCH(K8,ID_IT,0)-1) -> -1 | L29: =IF(L8="",-1,MATCH(L8,ID_IT,0)-1) -> 3 | M29: =IF(M8="",-1,MATCH(M8,ID_IT,0)-1) -> 3 | N29: =IF(N8="",-1,MATCH(N8,ID_IT,0)-1) -> 3 | O29: =IF(O8="",-1,MATCH(O8,ID_IT,0)-1) -> -1 | ... DQ29: =IF(DQ8="",-1,MATCH(DQ8,ID_IT,0)-1) -> -1
F30: =F9 -> 5 | H30: =IF(H9="",-1,MATCH(H9,ID_IT,0)-1) -> -1 | I30: =IF(I9="",-1,MATCH(I9,ID_IT,0)-1) -> -1 | J30: =IF(J9="",-1,MATCH(J9,ID_IT,0)-1) -> -1 | K30: =IF(K9="",-1,MATCH(K9,ID_IT,0)-1) -> -1 | L30: =IF(L9="",-1,MATCH(L9,ID_IT,0)-1) -> -1 | M30: =IF(M9="",-1,MATCH(M9,ID_IT,0)-1) -> -1 | N30: =IF(N9="",-1,MATCH(N9,ID_IT,0)-1) -> -1 | O30: =IF(O9="",-1,MATCH(O9,ID_IT,0)-1) -> -1 | ... DQ30: =IF(DQ9="",-1,MATCH(DQ9,ID_IT,0)-1) -> -1
F31: =F10 -> 6 | H31: =IF(H10="",-1,MATCH(H10,ID_IT,0)-1) -> -1 | I31: =IF(I10="",-1,MATCH(I10,ID_IT,0)-1) -> -1 | J31: =IF(J10="",-1,MATCH(J10,ID_IT,0)-1) -> -1 | K31: =IF(K10="",-1,MATCH(K10,ID_IT,0)-1) -> -1 | L31: =IF(L10="",-1,MATCH(L10,ID_IT,0)-1) -> -1 | M31: =IF(M10="",-1,MATCH(M10,ID_IT,0)-1) -> -1 | N31: =IF(N10="",-1,MATCH(N10,ID_IT,0)-1) -> -1 | O31: =IF(O10="",-1,MATCH(O10,ID_IT,0)-1) -> -1 | ... DQ31: =IF(DQ10="",-1,MATCH(DQ10,ID_IT,0)-1) -> -1
F32: =F11 -> 7 | H32: =IF(H11="",-1,MATCH(H11,ID_IT,0)-1) -> -1 | I32: =IF(I11="",-1,MATCH(I11,ID_IT,0)-1) -> -1 | J32: =IF(J11="",-1,MATCH(J11,ID_IT,0)-1) -> -1 | K32: =IF(K11="",-1,MATCH(K11,ID_IT,0)-1) -> -1 | L32: =IF(L11="",-1,MATCH(L11,ID_IT,0)-1) -> -1 | M32: =IF(M11="",-1,MATCH(M11,ID_IT,0)-1) -> -1 | N32: =IF(N11="",-1,MATCH(N11,ID_IT,0)-1) -> -1 | O32: =IF(O11="",-1,MATCH(O11,ID_IT,0)-1) -> -1 | ... DQ32: =IF(DQ11="",-1,MATCH(DQ11,ID_IT,0)-1) -> -1
F33: 10 | H33: =IF(H12="",-1,MATCH(H12,ID_IT,0)-1) -> -1 | I33: =IF(I12="",-1,MATCH(I12,ID_IT,0)-1) -> -1 | J33: =IF(J12="",-1,MATCH(J12,ID_IT,0)-1) -> -1 | K33: =IF(K12="",-1,MATCH(K12,ID_IT,0)-1) -> -1 | L33: =IF(L12="",-1,MATCH(L12,ID_IT,0)-1) -> -1 | M33: =IF(M12="",-1,MATCH(M12,ID_IT,0)-1) -> -1 | N33: =IF(N12="",-1,MATCH(N12,ID_IT,0)-1) -> -1 | O33: =IF(O12="",-1,MATCH(O12,ID_IT,0)-1) -> -1 | ... DQ33: =IF(DQ12="",-1,MATCH(DQ12,ID_IT,0)-1) -> -1
F34: =F13 -> 20 | H34: =IF(H13="",-1,MATCH(H13,ID_IT,0)-1) -> -1 | I34: =IF(I13="",-1,MATCH(I13,ID_IT,0)-1) -> -1 | J34: =IF(J13="",-1,MATCH(J13,ID_IT,0)-1) -> -1 | K34: =IF(K13="",-1,MATCH(K13,ID_IT,0)-1) -> -1 | L34: =IF(L13="",-1,MATCH(L13,ID_IT,0)-1) -> -1 | M34: =IF(M13="",-1,MATCH(M13,ID_IT,0)-1) -> -1 | N34: =IF(N13="",-1,MATCH(N13,ID_IT,0)-1) -> -1 | O34: =IF(O13="",-1,MATCH(O13,ID_IT,0)-1) -> -1 | ... DQ34: =IF(DQ13="",-1,MATCH(DQ13,ID_IT,0)-1) -> -1
F35: =F4 -> 0 | H35: 1 | I35: 1 | J35: -0.733 | K35: 1 | L35: -1 | M35: 1 | N35: -1 | O35: 1 | P35: 1 | Q35: 0.9999 | R35: -1 | S35: -1 | T35: 1 | U35: 1 | V35: 0.99995831 | W35: -1 | X35: -1 | Y35: 1 | Z35: 1 | AA35: 1 | AB35: 185 | AC35: -1 | AD35: -1 | AE35: 1 | AF35: 1 | AG35: 1 | AH35: 1 | AI35: 1 | AJ35: 1 | AK35: 1 | AL35: 1 | AM35: -1 | AN35: 1 | AO35: -1 | AP35: 1 | AQ35: 1 | AR35: 0.999 | AS35: -1 | AT35: -1 | AU35: 1 | AV35: 1 | AW35: 0.999 | AX35: -1 | AY35: -1 | AZ35: 1 | BA35: 1 | BB35: 0.999 | BC35: -1 | BD35: -15.716216 | BE35: -1 | BF35: 1 | BG35: 1 | BH35: 0.9999 | BI35: -1 | BJ35: -1 | BK35: 1 | BL35: 1 | BM35: 0.99995831 | BN35: -1 | BO35: -1 | BP35: 1 | BQ35: -1 | BR35: 1 | BS35: 1 | BT35: 1 | BU35: 1 | BV35: -0.52199 | BW35: -1 | BX35: 1 | BY35: 1 | BZ35: 0.9999 | CA35: -1 | CB35: -1 | CC35: 1 | CD35: -0.522 | CE35: 1 | CF35: -1 | CG35: 1 | CH35: 1 | CI35: 1 | CJ35: -1 | CK35: -1 | CL35: 1 | CM35: -1 | CN35: -1 | CO35: -1 | CP35: -0.28490028 | CQ35: 1 | CR35: 1 | CS35: -1 | CT35: -1 | CU35: -1 | CV35: 1 | CW35: -1 | CX35: 1 | CY35: -1 | CZ35: 1 | DA35: -1 | DB35: 1 | DC35: -1 | DD35: 1 | DE35: -1 | DF35: 1 | DG35: -1 | DH35: 1 | DI35: -1 | DJ35: 1 | DK35: -1 | DL35: 1 | DM35: -1 | DN35: 1 | DO35: 1 | DP35: 0.6406 | DQ35: 0.6406
F36: =F5 -> 1 | H36: -4.0406667 | I36: -4.8253333 | J36: -1 | K36: -1 | L36: 1 | M36: -1 | N36: 1 | O36: -1 | S36: 0.999 | T36: -1 | X36: 1 | Y36: -1 | AA36: 0.6406 | AB36: 1 | AC36: 1 | AD36: 4.8846 | AE36: 1 | AG36: 1 | AI36: 1 | AJ36: 1 | AM36: 1.124 | AN36: 16.041667 | AO36: 0.97467943 | AP36: -1.0259784 | AT36: 0.97467943 | AU36: -1.0259784 | AY36: 0.9486833 | AZ36: -1.0540926 | BD36: 1 | BE36: 1 | BF36: -1 | BJ36: 0.999 | BK36: -1 | BO36: 1 | BP36: -1 | BQ36: 1 | BR36: -1 | BS36: -1.2987151 | BT36: -0.60145571 | BU36: -1.1522 | BV36: 1 | BW36: 1 | BX36: -1 | CB36: 1 | CC36: -1 | CD36: 0.522 | CE36: -6.444 | CF36: 1 | CG36: -1 | CK36: 1 | CL36: -1 | CM36: 1 | CN36: 1 | CO36: 1 | CP36: 1 | CS36: 1 | CT36: 1 | CU36: 1 | CV36: 1 | CW36: -1 | CX36: 1 | CY36: -1 | CZ36: 0.6406 | DA36: -0.6406 | DB36: 0.6406 | DC36: -0.6406 | DK36: -0.016144033 | DL36: -1 | DM36: 1
F37: =F6 -> 2 | H37: -0.66733333 | I37: 4.8253333 | J37: 1 | L37: -0.43271397 | M37: 0 | N37: -1 | O37: 0 | S37: -1 | T37: 0 | AB37: 0.8834148 | AG37: 0 | AI37: 0 | AJ37: 0 | AM37: 4.0705 | AO37: -1 | AP37: -1 | AT37: -1 | AU37: -1 | AY37: -1 | AZ37: -1 | BD37: 0 | BE37: -1 | BF37: 0 | BJ37: -1 | BK37: -1 | BO37: -2.1228 | BS37: -0.62651636 | BT37: -14.384816 | BU37: -1.3506 | BV37: -1.04106 | BW37: -1 | BX37: -1 | CD37: -0.006 | CE37: -0.52199 | CF37: -1 | CG37: -1 | CV37: 11 | CW37: 11
F38: =F7 -> 3 | H38: 0.66733333 | J38: 0.733 | L38: 0 | M38: 0 | N38: -0.80247 | S38: -0.12 | AO38: 0 | AT38: 0 | AU38: 0 | AY38: 0 | AZ38: 0 | BD38: 15.716216 | BE38: -0.86763677 | BJ38: -0.10615 | BK38: -0.10615 | BO38: 2.1228 | BS38: -0.1511926 | BT38: 14.384816 | BU38: 1.3506 | BV38: -0.29025 | BW38: -0.00174 | BX38: 0 | CD38: -1 | CE38: -0.40694 | CF38: -0.00061 | CG38: 0
F39: =F8 -> 4 | L39: 0.43271397 | M39: 0 | N39: 0.80247 | S39: 0.12 | AO39: 0 | AT39: 0 | AY39: 0 | BD39: 4.7049113 | BE39: 0.86763677 | BJ39: 0.10615 | BK39: 0.10615 | BS39: 0.1511926 | BT39: 1.663025 | BV39: 0.52199 | BW39: 0.00174 | BX39: 0 | CD39: 5.6839 | CE39: 0.52199 | CF39: 0.00061 | CG39: 0
F40: =F9 -> 5 | CD40: 56.46
...

Sheet AC_LM
B1: Row | C1: Column | F1: Activity_UpperLimit [AC_LM] | H1: GELP | I1: H2L | J1: MTS | K1: MTS2 | L1: AMS | M1: MCS | N1: =CASE!M3 -> NG_IS | O1: =CASE!N3 -> H2_IS | P1: =CASE!O3 -> LA_IS | Q1: =CASE!P3 -> MC_IS | R1: NGF | S1: H2F | T1: AMF
A2: AC_LMI | B2: =ROWS(AC_LMI) -> 1 | C2: =COLUMNS(AC_LMI) -> 13 | F2: ID | H2: =MATCH(H1,ID_AC,0)-1 -> 18 | I2: =MATCH(I1,ID_AC,0)-1 -> 59 | J2: =MATCH(J1,ID_AC,0)-1 -> 63 | K2: =MATCH(K1,ID_AC,0)-1 -> 64 | L2: =MATCH(L1,ID_AC,0)-1 -> 65 | M2: =MATCH(M1,ID_AC,0)-1 -> 74 | N2: =MATCH(N1,ID_AC,0)-1 -> 96 | O2: =MATCH(O1,ID_AC,0)-1 -> 100 | ... T2: =MATCH(T1,ID_AC,0)-1 -> 91
A3: AC_LMD | B3: =ROWS(AC_LMD) -> 1 | C3: =COLUMNS(AC_LMD) -> 13 | D3: 1 | E3: 1 | F3: =INDEX(ID_YR,D3) -> YR2050 | G3: =INDEX(ID_RG,E3) -> ALL | H3: =CASE!C18 -> 0 | I3: =CASE!H4 -> 0 | J3: =CASE!I4 -> -1 | K3: =CASE!J4 -> 0 | L3: =CASE!K4 -> 0 | M3: =CASE!L4 -> 0 | N3: =CASE!M4 -> -1 | O3: =CASE!N4 -> 0 | P3: =CASE!O4 -> 0 | ... T3: =CASE!S4 -> 0

Sheet NK
B1: Row | C1: Column | G1: =IND!A5 -> Nodal facility [NK] | I1: DACE1 | J1: DACE2 | K1: CXL | L1: NGL | M1: NGV | N1: NGS | O1: NGT | P1: LNGS | Q1: LNGT | R1: GTG | S1: HYG | T1: SPG | U1: WIG1 | V1: WIG2 | W1: BDG | X1: LWR | Y1: PPS | Z1: BTSS | AA1: BTSL | AB1: WEL | AC1: H2S | AD1: H2T | AE1: LH2S | AF1: LH2T | AG1: H2L | AH1: H2V | AI1: MTS | AJ1: MTS2 | AK1: AMS | AL1: HSP | AM1: AMMS | AN1: AMMT | AO1: MCS | AP1: DHG | AQ1: MCHS | AR1: MCHT | AS1: GBL | AT1: ABL | AU1: HBL | AV1: HPP | AW1: HCLD | AX1: HCUL | AY1: NG_IS | AZ1: NG_ES | BA1: H2_IS | BB1: H2_ES | BC1: LA_IS | BD1: LA_ES | BE1: MC_IS | BF1: MC_ES
A2: NKI | B2: 1 | C2: =COLUMNS(NKI) -> 50 | G2: ID | I2: =MATCH(I1,ID_NK,0)-1 -> 0 | J2: =MATCH(J1,ID_NK,0)-1 -> 1 | K2: =MATCH(K1,ID_NK,0)-1 -> 2 | L2: =MATCH(L1,ID_NK,0)-1 -> 3 | M2: =MATCH(M1,ID_NK,0)-1 -> 4 | N2: =MATCH(N1,ID_NK,0)-1 -> 5 | O2: =MATCH(O1,ID_NK,0)-1 -> 6 | P2: =MATCH(P1,ID_NK,0)-1 -> 7 | ... BF2: =MATCH(BF1,ID_NK,0)-1 -> 49
A3: NKF | B3: =ROWS(NKF) -> 6 | C3: =COLUMNS(NKF) -> 50 | G3: 0 | I3: DACE1 | J3: DACE2 | K3: CXL | L3: NGL | M3: NGV | N3: NSA | P3: LNSA | R3: GTG | S3: HYG | T3: SPG | U3: WIG1 | V3: WIG2 | W3: BDG | X3: LWR | Y3: PSA | Z3: BSAS | AA3: BSAL | AB3: WEL | AC3: HSA | AE3: LHSA | AG3: H2L | AH3: H2V | AI3: MTS | AJ3: MTS2 | AK3: AMS | AL3: HSP | AM3: AMSA | AO3: MCS | AP3: DHG | AQ3: MCSA | AS3: GBL | AT3: ABL | AU3: HBL | AV3: HPP | AW3: LNLD | AX3: LNUL | AY3: NG_IS | AZ3: NG_ES | BA3: H2_IS | BB3: H2_ES | BC3: LA_IS | BD3: LA_ES | BE3: MC_IS | BF3: MC_ES
A4: NKD_1 | B4: =ROWS(NKD_1) -> 2 | C4: =COLUMNS(NKD_2) -> 50 | G4: 1 | S4: HYD | T4: SPD | U4: WID1 | V4: WID2 | AW4: LHLD | AX4: LHUL | BD4: AMMP
A5: NKD_2 | B5: =ROWS(NKD_2) -> 7 | C5: =COLUMNS(NKD_2) -> 50 | G5: 2 | AW5: AMLD | AX5: AMUL
A6: NKD_3 | B6: =ROWS(NKD_3) -> 1 | C6: =COLUMNS(NKD_3) -> 50 | G6: 3 | AW6: MCLD | AX6: MCUL
A7: Hydro | B7: =MATCH("HYG",ID_NK,0)-1 -> 10 | G7: 4
A8: Solar Wind | B8: =MATCH("SPG",ID_NK,0)-1 -> 11 | C8: =MATCH("WIG2",ID_NK,0)-1 -> 13 | G8: 5
A9: Storage (battery 1,2) | B9: =MATCH("PPS",ID_NK,0)-1 -> 16 | C9: =MATCH("BTSS",ID_NK,0)-1 -> 17 | G9: 0 | H9: =COUNT(NKF)-COUNTIF(NKF,-1) -> 55 | I9: =IF(I3="",-1,MATCH(I3,ID_AC,0)-1) -> 0 | J9: =IF(J3="",-1,MATCH(J3,ID_AC,0)-1) -> 1 | K9: =IF(K3="",-1,MATCH(K3,ID_AC,0)-1) -> 2 | L9: =IF(L3="",-1,MATCH(L3,ID_AC,0)-1) -> 4 | M9: =IF(M3="",-1,MATCH(M3,ID_AC,0)-1) -> 5 | N9: =IF(N3="",-1,MATCH(N3,ID_AC,0)-1) -> 8 | O9: =IF(O3="",-1,MATCH(O3,ID_AC,0)-1) -> -1 | P9: =IF(P3="",-1,MATCH(P3,ID_AC,0)-1) -> 13 | ... BF9: =IF(BF3="",-1,MATCH(BF3,ID_AC,0)-1) -> 107
A10: Storage (battery3) | B10: =MATCH("BTSL",ID_NK,0)-1 -> 18 | G10: 1 | I10: =IF(I4="",-1,MATCH(I4,ID_AC,0)-1) -> -1 | J10: =IF(J4="",-1,MATCH(J4,ID_AC,0)-1) -> -1 | K10: =IF(K4="",-1,MATCH(K4,ID_AC,0)-1) -> -1 | L10: =IF(L4="",-1,MATCH(L4,ID_AC,0)-1) -> -1 | M10: =IF(M4="",-1,MATCH(M4,ID_AC,0)-1) -> -1 | N10: =IF(N4="",-1,MATCH(N4,ID_AC,0)-1) -> -1 | O10: =IF(O4="",-1,MATCH(O4,ID_AC,0)-1) -> -1 | P10: =IF(P4="",-1,MATCH(P4,ID_AC,0)-1) -> -1 | ... BF10: =IF(BF4="",-1,MATCH(BF4,ID_AC,0)-1) -> -1
A11: Storage (H2, LH2) | B11: =MATCH("H2T",ID_NK,0)-1 -> 21 | C11: =MATCH("LH2T",ID_NK,0)-1 -> 23 | G11: 2 | I11: =IF(I5="",-1,MATCH(I5,ID_AC,0)-1) -> -1 | J11: =IF(J5="",-1,MATCH(J5,ID_AC,0)-1) -> -1 | K11: =IF(K5="",-1,MATCH(K5,ID_AC,0)-1) -> -1 | L11: =IF(L5="",-1,MATCH(L5,ID_AC,0)-1) -> -1 | M11: =IF(M5="",-1,MATCH(M5,ID_AC,0)-1) -> -1 | N11: =IF(N5="",-1,MATCH(N5,ID_AC,0)-1) -> -1 | O11: =IF(O5="",-1,MATCH(O5,ID_AC,0)-1) -> -1 | P11: =IF(P5="",-1,MATCH(P5,ID_AC,0)-1) -> -1 | ... BF11: =IF(BF5="",-1,MATCH(BF5,ID_AC,0)-1) -> -1
A12: Storage (CH4, LCH4) | B12: =MATCH("NGT",ID_NK,0)-1 -> 6 | C12: =MATCH("LNGT",ID_NK,0)-1 -> 8 | G12: 3 | I12: =IF(I6="",-1,MATCH(I6,ID_AC,0)-1) -> -1 | J12: =IF(J6="",-1,MATCH(J6,ID_AC,0)-1) -> -1 | K12: =IF(K6="",-1,MATCH(K6,ID_AC,0)-1) -> -1 | L12: =IF(L6="",-1,MATCH(L6,ID_AC,0)-1) -> -1 | M12: =IF(M6="",-1,MATCH(M6,ID_AC,0)-1) -> -1 | N12: =IF(N6="",-1,MATCH(N6,ID_AC,0)-1) -> -1 | O12: =IF(O6="",-1,MATCH(O6,ID_AC,0)-1) -> -1 | P12: =IF(P6="",-1,MATCH(P6,ID_AC,0)-1) -> -1 | ... BF12: =IF(BF6="",-1,MATCH(BF6,ID_AC,0)-1) -> -1
A13: Storage (MCH tank, NH3 tank) | B13: =MATCH("MCHT",ID_NK,0)-1 -> 35 | C13: =MATCH("AMMT",ID_NK,0)-1 -> 31 | G13: 4 | I13: =IF(I7="",-1,MATCH(I7,ID_AC,0)-1) -> -1 | J13: =IF(J7="",-1,MATCH(J7,ID_AC,0)-1) -> -1 | K13: =IF(K7="",-1,MATCH(K7,ID_AC,0)-1) -> -1 | L13: =IF(L7="",-1,MATCH(L7,ID_AC,0)-1) -> -1 | M13: =IF(M7="",-1,MATCH(M7,ID_AC,0)-1) -> -1 | N13: =IF(N7="",-1,MATCH(N7,ID_AC,0)-1) -> -1 | O13: =IF(O7="",-1,MATCH(O7,ID_AC,0)-1) -> -1 | P13: =IF(P7="",-1,MATCH(P7,ID_AC,0)-1) -> -1 | ... BF13: =IF(BF7="",-1,MATCH(BF7,ID_AC,0)-1) -> -1
A14: Hydrogen carrier loading/unloading | B14: =MATCH("HCLD",ID_NK,0)-1 -> 40 | C14: =MATCH("HCUL",ID_NK,0)-1 -> 41 | G14: 5 | I14: =IF(I8="",-1,MATCH(I8,ID_AC,0)-1) -> -1 | J14: =IF(J8="",-1,MATCH(J8,ID_AC,0)-1) -> -1 | K14: =IF(K8="",-1,MATCH(K8,ID_AC,0)-1) -> -1 | L14: =IF(L8="",-1,MATCH(L8,ID_AC,0)-1) -> -1 | M14: =IF(M8="",-1,MATCH(M8,ID_AC,0)-1) -> -1 | N14: =IF(N8="",-1,MATCH(N8,ID_AC,0)-1) -> -1 | O14: =IF(O8="",-1,MATCH(O8,ID_AC,0)-1) -> -1 | P14: =IF(P8="",-1,MATCH(P8,ID_AC,0)-1) -> -1 | ... BF14: =IF(BF8="",-1,MATCH(BF8,ID_AC,0)-1) -> -1
A15: Nuclear | B15: =MATCH("LWR",ID_NK,0)-1 -> 15 | G15: Unit | I15: Mt-C/yr | J15: Mt-C/yr | K15: Mt-C/yr | L15: Mtoe/yr | M15: Mtoe/yr | N15: GW | O15: GWh | P15: GW | Q15: GWh | R15: GW | S15: GW | T15: GW | U15: GW | V15: GW | W15: GW | X15: GW | Y15: GW | Z15: GW | AA15: GW | AB15: GWe | AC15: GW | AD15: GWh | AE15: GW | AF15: GWh | AG15: Mtoe/yr | AH15: Mtoe/yr | AI15: Mtoe/yr | AJ15: Mtoe/yr | AK15: Mtoe/yr | AL15: Mtoe-H2out/yr | AM15: GW | AN15: GWh | AO15: Mtoe-H2in/yr | AP15: Mtoe/yr | AQ15: MtMCH/yr | AR15: MtMCH | AS15: Mtoe/yr | AT15: Mtoe/yr | AU15: Mtoe/yr | AV15: kW-th | AW15: Mtoe/yr | AX15: Mtoe/yr | AY15: Mtoe/yr | AZ15: Mtoe/yr | BA15: Mtoe/yr | BB15: Mtoe/yr | BC15: Mtoe/yr | BD15: Mtoe/yr | BE15: MtMCH/yr | BF15: MtMCH/yr
A16: NK_LAF | B16: =ROWS(NK_LAF) -> 2 | C16: =COLUMNS(NK_LAF) -> 3 | G16: Time profile [positive: renewable power plants, 0: dispatchable power plants, -1: other plants] | H16: =MAX(I16:BF16) -> 6 | I16: -1 | J16: -1 | K16: -1 | L16: 0 | M16: -1 | N16: -1 | O16: -1 | P16: -1 | Q16: -1 | R16: 0 | S16: 1 | T16: 2 | U16: 3 | V16: 4 | W16: 0 | X16: 0 | Y16: =-1 -> -1 | Z16: -1 | AA16: -1 | AB16: 0 | AC16: -1 | AD16: -1 | AE16: -1 | AF16: -1 | AG16: 0 | AH16: -1 | AI16: 0 | AJ16: 0 | AK16: 0 | AL16: -1 | AM16: -1 | AN16: -1 | AO16: 0 | AP16: -1 | AQ16: -1 | AR16: -1 | AS16: -1 | AT16: -1 | AU16: -1 | AV16: -1 | AW16: 5 | AX16: 6 | AY16: -1 | AZ16: -1 | BA16: -1 | BB16: -1 | BC16: -1 | BD16: -1 | BE16: -1 | BF16: -1
A17: NK_LCC | B17: =ROWS(NK_LCC) -> 2 | C17: =COLUMNS(NK_LCC) -> 4 | G17: Operational info | I17: =IF(I16=0,IFERROR(MATCH(I2,NK_OPI,0)-1,"Error"),-1) -> -1 | J17: =IF(J16=0,IFERROR(MATCH(J2,NK_OPI,0)-1,"Error"),-1) -> -1 | K17: =IF(K16=0,IFERROR(MATCH(K2,NK_OPI,0)-1,"Error"),-1) -> -1 | L17: =IF(L16=0,IFERROR(MATCH(L2,NK_OPI,0)-1,"Error"),-1) -> 0 | M17: =IF(M16=0,IFERROR(MATCH(M2,NK_OPI,0)-1,"Error"),-1) -> -1 | N17: =IF(N16=0,IFERROR(MATCH(N2,NK_OPI,0)-1,"Error"),-1) -> -1 | O17: =IF(O16=0,IFERROR(MATCH(O2,NK_OPI,0)-1,"Error"),-1) -> -1 | P17: =IF(P16=0,IFERROR(MATCH(P2,NK_OPI,0)-1,"Error"),-1) -> -1 | ... BF17: =IF(BF16=0,IFERROR(MATCH(BF2,NK_OPI,0)-1,"Error"),-1) -> -1
A18: NK_KI | B18: =ROWS(NK_KI) -> 1 | C18: =COLUMNS(NK_KI) -> 14 | G18: Unit conversion | I18: 1 | J18: 1 | K18: 1 | L18: 1 | M18: 1 | N18: =8.76/B35 -> 0.75322442 | O18: 1 | P18: =8.76/B35 -> 0.75322442 | Q18: 1 | R18: 8.76 | S18: 8.76 | T18: 8.76 | U18: 8.76 | V18: 8.76 | W18: 8.76 | X18: 8.76 | Y18: 8.76 | Z18: 8.76 | AA18: 8.76 | AB18: 8.76 | AC18: =8.76/B35 -> 0.75322442 | AD18: 1 | AE18: =8.76/B35 -> 0.75322442 | AF18: 1 | AG18: 1 | AH18: 1 | AI18: 1 | AJ18: 1 | AK18: 1 | AL18: 1 | AM18: =8.76/B35 -> 0.75322442 | AN18: 1 | AO18: 1 | AP18: 1 | AQ18: 1 | AR18: 1 | AS18: 1 | AT18: 1 | AU18: 1 | AV18: 8.76 | AW18: 1 | AX18: 1 | AY18: 1 | AZ18: 1 | BA18: 1 | BB18: 1 | BC18: 1 | BD18: 1 | BE18: 1 | BF18: 1
A19: NK_EKD | B19: =ROWS(NK_EKD) -> 2 | C19: =COLUMNS(NK_EKD) -> 14 | G19: Max. capacity factor | I19: 0.95 | J19: 0.95 | K19: 0.95 | L19: 0.95 | M19: 0.95 | N19: 0.95 | O19: 1 | P19: 0.95 | Q19: 1 | R19: 1 | S19: 1 | T19: 1 | U19: 1 | V19: 1 | W19: 1 | X19: 0.7 | Y19: 0.95 | Z19: 0.95 | AA19: 0.95 | AB19: 0.95 | AC19: 0.95 | AD19: 1 | AE19: 0.95 | AF19: 1 | AG19: 0.95 | AH19: 0.95 | AI19: 0.95 | AJ19: 0.95 | AK19: 0.95 | AL19: 0.95 | AM19: 0.95 | AN19: 1 | AO19: 0.95 | AP19: 0.95 | AQ19: 0.95 | AR19: 1 | AS19: 0.95 | AT19: 0.95 | AU19: 0.95 | AV19: 0.95 | AW19: 1 | AX19: 1 | AY19: 0.95 | AZ19: 0.95 | BA19: 0.95 | BB19: 0.95 | BC19: 0.95 | BD19: 0.95 | BE19: 0.95 | BF19: 0.95
A20: NK_MKD | B20: =ROWS(NK_MKD) -> 2 | C20: =COLUMNS(NK_MKD) -> 14 | G20: Hourly min. capacity factor | I20: 0 | J20: 0 | K20: 0 | L20: 0.3 | M20: 0 | N20: 0 | O20: 0 | P20: 0 | Q20: 0 | R20: 0 | S20: 0 | T20: 0 | U20: 0 | V20: 0 | W20: 0 | X20: 0 | Y20: 0 | Z20: 0 | AA20: 0 | AB20: 0.1 | AC20: 0 | AD20: 0 | AE20: 0 | AF20: 0 | AG20: 0.3 | AH20: 0 | AI20: 0.3 | AJ20: 0.7 | AK20: 0.3 | AL20: 0.3 | AM20: 0 | AN20: 0 | AO20: 0.3 | AP20: 0.3 | AQ20: 0 | AR20: 0 | AS20: 0 | AT20: 0 | AU20: 0 | AV20: 0 | AW20: 0 | AX20: 0 | AY20: 0 | AZ20: 0 | BA20: 0 | BB20: 0 | BC20: 0 | BD20: 0 | BE20: 0 | BF20: 0
A21: Water electrolysis | B21: =MATCH("WEL",ID_NK,0)-1 -> 19 | G21: Annualize factor | I21: =IND!$BE$5/(1-(1+IND!$BE$5)^-I24)+I26 -> 0.13367878 | J21: =IND!$BE$5/(1-(1+IND!$BE$5)^-J24)+J26 -> 0.13067878 | K21: 1 | L21: =IND!$BE$5/(1-(1+IND!$BE$5)^-L24)+L26 -> 0.12882743 | M21: =IND!$BE$5/(1-(1+IND!$BE$5)^-M24)+M26 -> 0.12882743 | N21: =IND!$BE$5/(1-(1+IND!$BE$5)^-N24)+N26 -> 0.12682954 | O21: =IND!$BE$5/(1-(1+IND!$BE$5)^-O24)+O26 -> 0.12682954 | P21: =IND!$BE$5/(1-(1+IND!$BE$5)^-P24)+P26 -> 0.098827433 | Q21: =IND!$BE$5/(1-(1+IND!$BE$5)^-Q24)+Q26 -> 0.098827433 | R21: =IND!$BE$5/(1-(1+IND!$BE$5)^-R24)+R26 -> 0.12386016 | S21: =IND!$BE$5/(1-(1+IND!$BE$5)^-S24)+S26 -> 0.10979795 | ... BF21: =IND!$BE$5/(1-(1+IND!$BE$5)^-BF24)+BF26 -> 0.12882743
A22: Importing and exporting terminal | B22: =MATCH("NG_IS",ID_NK,0)-1 -> 42 | C22: =MATCH("MC_ES",ID_NK,0)-1 -> 49 | G22: Location type (availability factor) | I22: 0 | J22: 0 | K22: 0 | L22: 0 | M22: 0 | N22: 0 | O22: 0 | P22: 0 | Q22: 0 | R22: 0 | S22: 0 | T22: 0 | U22: 0 | V22: 0 | W22: 0 | X22: 0 | Y22: 0 | Z22: 0 | AA22: 0 | AB22: 0 | AC22: 0 | AD22: 0 | AE22: 0 | AF22: 0 | AG22: 0 | AH22: 0 | AI22: 0 | AJ22: 0 | AK22: 0 | AL22: 0 | AM22: 0 | AN22: 0 | AO22: 0 | AP22: 0 | AQ22: 0 | AR22: 0 | AS22: 0 | AT22: 0 | AU22: 0 | AV22: 0 | AW22: 0 | AX22: 0 | AY22: 0 | AZ22: 0 | BA22: 0 | BB22: 0 | BC22: 0 | BD22: 0 | BE22: 0 | BF22: 0
A23: Direct air capture | B23: =MATCH("DACE1",ID_NK,0)-1 -> 0 | C23: =MATCH("DACE2",ID_NK,0)-1 -> 1 | G23: Location type (capital cost) | I23: 0 | J23: 0 | K23: 0 | L23: 0 | M23: 0 | N23: 0 | O23: 0 | P23: 0 | Q23: 0 | R23: 0 | S23: 0 | T23: 1 | U23: 2 | V23: 3 | W23: 0 | X23: 0 | Y23: 0 | Z23: 0 | AA23: 0 | AB23: 0 | AC23: 0 | AD23: 0 | AE23: 0 | AF23: 0 | AG23: 0 | AH23: 0 | AI23: 0 | AJ23: 0 | AK23: 0 | AL23: 0 | AM23: 0 | AN23: 0 | AO23: 0 | AP23: 0 | AQ23: 0 | AR23: 0 | AS23: 0 | AT23: 0 | AU23: 0 | AV23: 0 | AW23: 0 | AX23: 0 | AY23: 0 | AZ23: 0 | BA23: 0 | BB23: 0 | BC23: 0 | BD23: 0 | BE23: 0 | BF23: 0
A24: H2 carrier conversion CH4 | B24: =MATCH("NGL",ID_NK,0)-1 -> 3 | C24: =MATCH("NGV",ID_NK,0)-1 -> 4 | G24: Lifetime | I24: 25 | J24: 25 | K24: 30 | L24: 30 | M24: 30 | N24: 15 | O24: 15 | P24: 30 | Q24: 30 | R24: 40 | S24: 60 | T24: 25 | U24: 25 | V24: 25 | W24: 40 | X24: 40 | Y24: 15 | Z24: 15 | AA24: 15 | AB24: 15 | AC24: 15 | AD24: 15 | AE24: 30 | AF24: 30 | AG24: 30 | AH24: 30 | AI24: 30 | AJ24: 30 | AK24: 30 | AL24: 30 | AM24: 30 | AN24: 30 | AO24: 30 | AP24: 30 | AQ24: 30 | AR24: 30 | AS24: 30 | AT24: 30 | AU24: 30 | AV24: 30 | AW24: 30 | AX24: 30 | AY24: 30 | AZ24: 30 | BA24: 30 | BB24: 30 | BC24: 30 | BD24: 30 | BE24: 30 | BF24: 30
A25: H2 carrier conversion CH4 | B25: =MATCH("MTS",ID_NK,0)-1 -> 26 | F25: 1 | G25: Capital cost | H25: =INDEX(ID_YR,F25) -> YR2050 | I25: 933.13141 | J25: 1040.9808 | K25: 46.44 | L25: 808.06287 | M25: 0 | N25: 728.05672 | O25: 15.556768 | P25: 0.0001 | Q25: 0.20132365 | R25: 408.91984 | S25: 999999 | T25: 179.92473 | U25: 948.69404 | V25: 1570.2522 | W25: 999999 | X25: 999999 | Y25: 601.39645 | Z25: 877.57726 | AA25: 1429.9372 | AB25: 450 | AC25: 728.05672 | AD25: 15.556768 | AE25: 0.0001 | AF25: 2.72 | AG25: 1873.8204 | AH25: 0 | AI25: 750 | AJ25: 1313.6818 | AK25: 1386.6 | AL25: 718.64 | AM25: 0.0001 | AN25: 0.38596159 | AO25: 488.6846 | AP25: 965.088 | AQ25: 0.0001 | AR25: 761.90476 | AS25: 149.5 | AT25: 149.5 | AU25: 149.5 | AV25: 704.9 | AW25: 0.0001 | AX25: 0.0001 | AY25: 0 | AZ25: 0 | BA25: 0 | BB25: 0 | BC25: 0 | BD25: 0 | BE25: 0 | BF25: 0
A26: H2 carrier conversion CH4 | B26: =MATCH("MTS2",ID_NK,0)-1 -> 27 | G26: Fixed O&M ratio | I26: 0.04 | J26: 0.037 | L26: 0.04 | M26: 0.04 | N26: =AC26 -> 0.01 | O26: =AD26 -> 0.01 | P26: 0.01 | Q26: 0.01 | R26: 0.04 | S26: 0.029 | T26: =8/T25 -> 0.044463037 | U26: =30/U25 -> 0.031622419 | V26: =60/V25 -> 0.038210422 | W26: 0.035 | X26: 0.063 | Y26: =14.62/Y25 -> 0.024310087 | Z26: =22.481/Z25 -> 0.025617118 | AA26: =38.205/AA25 -> 0.026717957 | AB26: 0.015 | AC26: 0.01 | AD26: 0.01 | AE26: 0.04 | AF26: 0.04 | AG26: 0.04 | AH26: 0.04 | AI26: 0.05 | AJ26: 0.05 | AK26: 0.029 | AL26: 0.05 | AM26: 0.04 | AN26: 0.04 | AO26: 0.02391772 | AP26: 0.04 | AQ26: 0.04 | AR26: 0.04 | AS26: 0.04 | AT26: 0.04 | AU26: 0.04 | AV26: =2/530 -> 0.0037735849 | AW26: 0.04 | AX26: 0.04 | AY26: 0.04 | AZ26: 0.04 | BA26: 0.04 | BB26: 0.04 | BC26: 0.04 | BD26: 0.04 | BE26: 0.04 | BF26: 0.04
A27: H2 carrier conversion LH2 | B27: =MATCH("H2L",ID_NK,0)-1 -> 24 | C27: =MATCH("H2V",ID_NK,0)-1 -> 25
A28: H2 carrier conversion NH3 | B28: =MATCH("AMS",ID_NK,0)-1 -> 28 | C28: =MATCH("HSP",ID_NK,0)-1 -> 29 | G28: Location Factor (Availability factor/Capital cost) | I28: Type0 | J28: Type1 | K28: Type2 | L28: Type0 | M28: Type1 | N28: Type2 | O28: Type3
A29: H2 carrier conversion MCH | B29: =MATCH("MCS",ID_NK,0)-1 -> 32 | C29: =MATCH("DHG",ID_NK,0)-1 -> 33 | F29: 1 | G29: =INDEX(ID_ND,F29) -> EXP | I29: 1 | J29: 1 | K29: 1 | L29: 1 | M29: 1 | N29: 1 | O29: 1
A30: H2 and CH4 storage compressor | B30: =MATCH("NGS",ID_NK,0)-1 -> 5 | C30: =MATCH("H2S",ID_NK,0)-1 -> 20 | F30: =IF(F29+1>COUNTA(ID_ND),1,F29+1) -> 2 | G30: =INDEX(ID_ND,F30) -> IMP | I30: 1 | J30: 1 | K30: 1 | L30: 1 | M30: =880/T25 -> 4.8909341 | N30: =2070/U25 -> 2.1819469 | O30: =2380/V25 -> 1.5156801
A34: Conversion factor | G34: Existing/maximum capacity | I34: NGL | J34: NGV | K34: HYG | L34: SPG | M34: WIG1 | N34: WIG2 | O34: BDG | P34: LWR | Q34: WEL | R34: H2L | S34: MTS | T34: MTS2 | U34: AMS | V34: MCS
A35: Mtoe->TWh | B35: 11.63 | G35: ID | I35: =MATCH(I34,ID_NK,0)-1 -> 3 | J35: =MATCH(J34,ID_NK,0)-1 -> 4 | K35: =MATCH(K34,ID_NK,0)-1 -> 10 | L35: =MATCH(L34,ID_NK,0)-1 -> 11 | M35: =MATCH(M34,ID_NK,0)-1 -> 12 | N35: =MATCH(N34,ID_NK,0)-1 -> 13 | O35: =MATCH(O34,ID_NK,0)-1 -> 14 | P35: =MATCH(P34,ID_NK,0)-1 -> 15 | ... V35: =MATCH(V34,ID_NK,0)-1 -> 32
A36: TWh->PJ | B36: 3.6 | G36: Unit | I36: Mtoe/year | J36: Mtoe/year | K36: GW | L36: GW | M36: GW | N36: GW | O36: GW | P36: GW
E37: 1 | F37: 1 | G37: =INDEX(ID_YR,E37) -> YR2050 | H37: =INDEX(ID_ND,F37) -> EXP | I37: 0 | J37: 0 | K37: 0 | L37: 0 | M37: 0 | N37: 0 | O37: 0 | P37: 0 | Q37: 0 | R37: 0 | S37: 0 | T37: 0 | U37: 0 | V37: 0
E38: =IF(F38=1,E37+1,E37) -> 1 | F38: =IF(F37+1>COUNTA(ID_ND),1,F37+1) -> 2 | G38: =INDEX(ID_YR,E38) -> YR2050 | H38: =INDEX(ID_ND,F38) -> IMP | I38: 0 | J38: 0 | K38: 0 | L38: 0 | M38: 0 | N38: 0 | O38: 0 | P38: 0 | Q38: 0 | R38: 0 | S38: 0 | T38: 0 | U38: 0 | V38: 0
I39: -1 | J39: 0 | K39: -1 | L39: -1 | M39: -1 | N39: 0 | O39: 0 | P39: 0 | Q39: -1 | R39: -1 | S39: -1 | T39: -1 | U39: -1 | V39: -1
I40: 0 | J40: -1 | K40: 0 | L40: -1 | M40: -1 | N40: 0 | O40: 0 | P40: 0 | Q40: 0 | R40: 0 | S40: 0 | T40: 0 | U40: 0 | V40: 0

Sheet NK_OP
B1: Row | C1: Column | G1: Nodal Facility Maintenance Schedule [NK_MS] | H1: DY1 | I1: DY2 | J1: DY3 | K1: DY4 | L1: DY5 | M1: DY6 | N1: DY7 | O1: DY8 | P1: DY9 | Q1: DY10 | R1: DY11 | S1: DY12 | T1: DY13 | U1: DY14 | V1: DY15 | W1: DY16 | X1: DY17 | Y1: DY18 | Z1: DY19 | AA1: DY20 | AB1: DY21 | AC1: DY22 | AD1: DY23 | AE1: DY24 | AF1: DY25 | AG1: DY26 | AH1: DY27 | AI1: DY28 | AJ1: DY29 | AK1: DY30 | AL1: DY31 | AM1: DY32 | AN1: DY33 | AO1: DY34 | AP1: DY35 | AQ1: DY36 | AR1: DY37 | AS1: DY38 | AT1: DY39 | AU1: DY40 | AV1: DY41 | AW1: DY42 | AX1: DY43 | AY1: DY44 | AZ1: DY45 | BA1: DY46 | BB1: DY47 | BC1: DY48 | BD1: DY49 | BE1: DY50 | BF1: DY51 | BG1: DY52 | BH1: DY53 | BI1: DY54 | BJ1: DY55 | BK1: DY56 | BL1: DY57 | BM1: DY58 | BN1: DY59 | BO1: DY60 | BP1: DY61 | BQ1: DY62 | BR1: DY63 | BS1: DY64 | BT1: DY65 | BU1: DY66 | BV1: DY67 | BW1: DY68 | BX1: DY69 | BY1: DY70 | BZ1: DY71 | CA1: DY72 | CB1: DY73 | CC1: DY74 | CD1: DY75 | CE1: DY76 | CF1: DY77 | CG1: DY78 | CH1: DY79 | CI1: DY80 | CJ1: DY81 | CK1: DY82 | CL1: DY83 | CM1: DY84 | CN1: DY85 | CO1: DY86 | CP1: DY87 | CQ1: DY88 | CR1: DY89 | CS1: DY90 | CT1: DY91 | CU1: DY92 | CV1: DY93 | CW1: DY94 | CX1: DY95 | CY1: DY96 | CZ1: DY97 | DA1: DY98 | DB1: DY99 | DC1: DY100 | DD1: DY101 | DE1: DY102 | DF1: DY103 | DG1: DY104 | DH1: DY105 | DI1: DY106 | DJ1: DY107 | DK1: DY108 | DL1: DY109 | DM1: DY110 | DN1: DY111 | DO1: DY112 | DP1: DY113 | DQ1: DY114 | DR1: DY115 | DS1: DY116 | DT1: DY117 | DU1: DY118 | DV1: DY119 | DW1: DY120 | DX1: DY121 | DY1: DY122 | DZ1: DY123 | EA1: DY124 | EB1: DY125 | EC1: DY126 | ED1: DY127 | EE1: DY128 | EF1: DY129 | EG1: DY130 | EH1: DY131 | EI1: DY132 | EJ1: DY133 | EK1: DY134 | EL1: DY135 | EM1: DY136 | EN1: DY137 | EO1: DY138 | EP1: DY139 | EQ1: DY140 | ER1: DY141 | ES1: DY142 | ET1: DY143 | EU1: DY144 | EV1: DY145 | EW1: DY146 | EX1: DY147 | EY1: DY148 | EZ1: DY149 | FA1: DY150 | FB1: DY151 | FC1: DY152 | FD1: DY153 | FE1: DY154 | FF1: DY155 | FG1: DY156 | FH1: DY157 | FI1: DY158 | FJ1: DY159 | FK1: DY160 | FL1: DY161 | FM1: DY162 | FN1: DY163 | FO1: DY164 | FP1: DY165 | FQ1: DY166 | FR1: DY167 | FS1: DY168 | FT1: DY169 | FU1: DY170 | FV1: DY171 | FW1: DY172 | FX1: DY173 | FY1: DY174 | FZ1: DY175 | GA1: DY176 | GB1: DY177 | GC1: DY178 | GD1: DY179 | GE1: DY180 | GF1: DY181 | GG1: DY182 | GH1: DY183 | GI1: DY184 | GJ1: DY185 | GK1: DY186 | GL1: DY187 | GM1: DY188 | GN1: DY189 | GO1: DY190 | GP1: DY191 | GQ1: DY192 | GR1: DY193 | GS1: DY194 | GT1: DY195 | GU1: DY196 | GV1: DY197 | GW1: DY198 | GX1: DY199 | GY1: DY200 | GZ1: DY201 | HA1: DY202 | HB1: DY203 | HC1: DY204 | HD1: DY205 | HE1: DY206 | HF1: DY207 | HG1: DY208 | HH1: DY209 | HI1: DY210 | HJ1: DY211 | HK1: DY212 | HL1: DY213 | HM1: DY214 | HN1: DY215 | HO1: DY216 | HP1: DY217 | HQ1: DY218 | HR1: DY219 | HS1: DY220 | HT1: DY221 | HU1: DY222 | HV1: DY223 | HW1: DY224 | HX1: DY225 | HY1: DY226 | HZ1: DY227 | IA1: DY228 | IB1: DY229 | IC1: DY230 | ID1: DY231 | IE1: DY232 | IF1: DY233 | IG1: DY234 | IH1: DY235 | II1: DY236 | IJ1: DY237 | IK1: DY238 | IL1: DY239 | IM1: DY240 | IN1: DY241 | IO1: DY242 | IP1: DY243 | IQ1: DY244 | IR1: DY245 | IS1: DY246 | IT1: DY247 | IU1: DY248 | IV1: DY249 | IW1: DY250 | IX1: DY251 | IY1: DY252 | IZ1: DY253 | JA1: DY254 | JB1: DY255 | JC1: DY256 | JD1: DY257 | JE1: DY258 | JF1: DY259 | JG1: DY260 | JH1: DY261 | JI1: DY262 | JJ1: DY263 | JK1: DY264 | JL1: DY265 | JM1: DY266 | JN1: DY267 | JO1: DY268 | JP1: DY269 | JQ1: DY270 | JR1: DY271 | JS1: DY272 | JT1: DY273 | JU1: DY274 | JV1: DY275 | JW1: DY276 | JX1: DY277 | JY1: DY278 | JZ1: DY279 | KA1: DY280 | KB1: DY281 | KC1: DY282 | KD1: DY283 | KE1: DY284 | KF1: DY285 | KG1: DY286 | KH1: DY287 | KI1: DY288 | KJ1: DY289 | KK1: DY290 | KL1: DY291 | KM1: DY292 | KN1: DY293 | KO1: DY294 | KP1: DY295 | KQ1: DY296 | KR1: DY297 | KS1: DY298 | KT1: DY299 | KU1: DY300 | KV1: DY301 | KW1: DY302 | KX1: DY303 | KY1: DY304 | KZ1: DY305 | LA1: DY306 | LB1: DY307 | LC1: DY308 | LD1: DY309 | LE1: DY310 | LF1: DY311 | LG1: DY312 | LH1: DY313 | LI1: DY314 | LJ1: DY315 | LK1: DY316 | LL1: DY317 | LM1: DY318 | LN1: DY319 | LO1: DY320 | LP1: DY321 | LQ1: DY322 | LR1: DY323 | LS1: DY324 | LT1: DY325 | LU1: DY326 | LV1: DY327 | LW1: DY328 | LX1: DY329 | LY1: DY330 | LZ1: DY331 | MA1: DY332 | MB1: DY333 | MC1: DY334 | MD1: DY335 | ME1: DY336 | MF1: DY337 | MG1: DY338 | MH1: DY339 | MI1: DY340 | MJ1: DY341 | MK1: DY342 | ML1: DY343 | MM1: DY344 | MN1: DY345 | MO1: DY346 | MP1: DY347 | MQ1: DY348 | MR1: DY349 | MS1: DY350 | MT1: DY351 | MU1: DY352 | MV1: DY353 | MW1: DY354 | MX1: DY355 | MY1: DY356 | MZ1: DY357 | NA1: DY358 | NB1: DY359 | NC1: DY360 | ND1: DY361 | NE1: DY362 | NF1: DY363 | NG1: DY364 | NH1: DY365
A2: NK_MSI | B2: =ROWS(NK_MSI) -> 1 | C2: =COLUMNS(NK_MSI) -> 365 | G2: Day ID | H2: =MATCH(H1,ID_DY,0)-1 -> 0 | I2: =MATCH(I1,ID_DY,0)-1 -> 1 | J2: =MATCH(J1,ID_DY,0)-1 -> 2 | K2: =MATCH(K1,ID_DY,0)-1 -> 3 | L2: =MATCH(L1,ID_DY,0)-1 -> 4 | M2: =MATCH(M1,ID_DY,0)-1 -> 5 | N2: =MATCH(N1,ID_DY,0)-1 -> 6 | O2: =MATCH(O1,ID_DY,0)-1 -> 7 | ... NH2: =MATCH(NH1,ID_DY,0)-1 -> 364
